Workbook

Sheet 1
A1: Daily achievement sheet (Van/Cluster/Singel /Welimada/DLS Oparations)
A2: Sr | B2: Item Description | M2: ASE
B3: RMS Items | C3: Avissawella | D3: Rathnapura | E3: Hanwella | F3: Horana | G3: Balangoda | H3: Piliyandala | M3: Tatal (B)
A4: 1 | B4: High Sugar- 500gr (Angel) | M4: =SUM(C4:L4) -> 0
A5: 2 | B5: Low Sugar -450gr (Angle) | M5: =SUM(C5:L5) -> 0
A6: 3 | B6: Low Sugar -500gr (Angle) | M6: =SUM(C6:L6) -> 0
A7: 4 | B7: Gloripan Instant Dry Yeast (High Sugar) 500g | M7: =SUM(C7:L7) -> 0
A8: 5 | B8: Gloripan Instant Dry Yeast (Low Sugar) 500g | M8: =SUM(C8:L8) -> 0
A9: 6 | B9: 2 In 1 Yeast 500gr (Low Suger) | M9: =SUM(C9:L9) -> 0
A10: 7 | B10: 2 In 1 Yeast 500gr (High Suger) | M10: =SUM(C10:L10) -> 0
A11: 8 | B11: Bakery Yest total | C11: =SUM(C4:C10) -> 0 | D11: =SUM(D4:D10) -> 0 | E11: =SUM(E4:E10) -> 0 | F11: =SUM(F4:F10) -> 0 | G11: =SUM(G4:G10) -> 0 | H11: =SUM(H4:H10) -> 0 | I11: =SUM(I4:I10) -> 0 | J11: =SUM(J4:J10) -> 0 | ... L11: =SUM(L4:L10) -> 0 | M11: =SUM(C11:L11) -> 0
A12: 9 | B12: Instant Leaven -450gr | M12: =SUM(C12:L12) -> 0
A13: 10 | B13: Instant Leaven -500gr | M13: =SUM(C13:L13) -> 0
A14: 11 | B14: Leaven Total | C14: =SUM(C12:C13) -> 0 | D14: =SUM(D12:D13) -> 0 | E14: =SUM(E12:E13) -> 0 | F14: =SUM(F12:F13) -> 0 | G14: =SUM(G12:G13) -> 0 | H14: =SUM(H12:H13) -> 0 | I14: =SUM(I12:I13) -> 0 | J14: =SUM(J12:J13) -> 0 | ... L14: =SUM(L12:L13) -> 0 | M14: =SUM(C14:L14) -> 0
A15: 12 | B15: Shortening- 15 kg | M15: =SUM(C15:L15) -> 0
A16: 13 | B16: Total Yest | C16: =C11+C14 -> 0 | D16: =D11+D14 -> 0 | E16: =E11+E14 -> 0 | F16: =F11+F14 -> 0 | G16: =G11+G14 -> 0 | H16: =H11+H14 -> 0 | I16: =I11+I14 -> 0 | J16: =J11+J14 -> 0 | ... L16: =L11+L14 -> 0 | M16: =SUM(C16:L16) -> 0
A17: 14 | B17: Angle Dry Yeast 25g | M17: =SUM(C17:L17) -> 0
A18: 15 | B18: Angle Dry Yeast 50g | M18: =SUM(C18:L18) -> 0
A19: 16 | B19: Total Angle Dry Yeast | C19: =SUM(C17:C18) -> 0 | D19: =SUM(D17:D18) -> 0 | E19: =SUM(E17:E18) -> 0 | F19: =SUM(F17:F18) -> 0 | G19: =SUM(G17:G18) -> 0 | H19: =SUM(H17:H18) -> 0 | I19: =SUM(I17:I18) -> 0 | J19: =SUM(J17:J18) -> 0 | ... M19: =SUM(M17:M18) -> 0
A20: 17 | B20: Mitra Margerine (Bakers compound -15kg) | M20: =SUM(C20:L20) -> 0
A21: 18 | B21: Mitra Margerine (Blue Lable) - 15kg | M21: =SUM(C21:L21) -> 0
A22: 19 | B22: Mitra - (Bun Compound 15Kg) | M22: =SUM(C22:L22) -> 0
A23: 20 | B23: Bakers Star Multy Purpes 15kg | M23: =SUM(C23:L23) -> 0
A24: 21 | B24: Bakers Star Primum Cake 15kg | M24: =SUM(C24:L24) -> 0
A25: 22 | B25: Mitra 15Kg (Bread Compound 15Kg) | M25: =SUM(C25:L25) -> 0
A26: 23 | B26: Bakers Star Pastry Margareen 15kg | M26: =SUM(C26:L26) -> 0
A27: 24 | B27: Bakers Star Creming Fat Margareen 15kg | M27: =SUM(C27:L27) -> 0
A28: 25 | B28: Total Magrgering | C28: =SUM(C20:C27) -> 0 | D28: =SUM(D20:D27) -> 0 | E28: =SUM(E20:E27) -> 0 | F28: =SUM(F20:F27) -> 0 | G28: =SUM(G20:G27) -> 0 | H28: =SUM(H20:H27) -> 0 | I28: =SUM(I20:I27) -> 0 | J28: =SUM(J20:J27) -> 0 | ... L28: =SUM(L20:L27) -> 0 | M28: =SUM(C28:L28) -> 0
A29: 26 | B29: Som-Chai 25kg bag | M29: =SUM(C29:L29) -> 0
A30: 27 | B30: Som-Chai G1 25kg bag | M30: =SUM(C30:L30) -> 0
A31: 28 | B31: Bread Improver- 01kg(LD-500) | M31: =SUM(C31:L31) -> 0
A32: 29 | B32: Bread Improver- 01kg(A-800) | M32: =SUM(C32:L32) -> 0
A33: 30 | B33: Som-Chai G2 25kg bag | M33: =SUM(C33:L33) -> 0
A34: 31 | B34: Som-Chai G2 1kg Pkt | M34: =SUM(C34:L34) -> 0
A35: 32 | B35: Som-Chai G2 350g Pkt | M35: =SUM(C35:L35) -> 0
A36: 33 | B36: Pan Grease- 5L | M36: =SUM(C36:L36) -> 0
A37: 34 | B37: Pan Grease- 20L | M37: =SUM(C37:L37) -> 0
A38: 35 | B38: Hybrid Noodles (Red) | M38: =SUM(C38:L38) -> 0
A39: 36 | B39: Isi PVD 400g | M39: =SUM(C39:L39) -> 0
A40: 37 | B40: Isi 1kg | M40: =SUM(C40:L40) -> 0
...

Sheet 2
A1: Daily achievement sheet (Van/Cluster/Singel /Welimada/DLS Oparations)
A2: Sr | B2: Item Description | M2: ASE
B3: RMS Items | C3: Avissawella | D3: Rathnapura | E3: Hanwella | F3: Horana | G3: Balangoda | H3: Piliyandala | M3: Tatal (B)
A4: 1 | B4: High Sugar- 500gr (Angel) | M4: =SUM(C4:L4) -> 0
A5: 2 | B5: Low Sugar -450gr (Angle) | M5: =SUM(C5:L5) -> 0
A6: 3 | B6: Low Sugar -500gr (Angle) | M6: =SUM(C6:L6) -> 0
A7: 4 | B7: Gloripan Instant Dry Yeast (High Sugar) 500g | M7: =SUM(C7:L7) -> 0
A8: 5 | B8: Gloripan Instant Dry Yeast (Low Sugar) 500g | M8: =SUM(C8:L8) -> 0
A9: 6 | B9: 2 In 1 Yeast 500gr (Low Suger) | M9: =SUM(C9:L9) -> 0
A10: 7 | B10: 2 In 1 Yeast 500gr (High Suger) | M10: =SUM(C10:L10) -> 0
A11: 8 | B11: Bakery Yest total | C11: =SUM(C4:C10) -> 0 | D11: =SUM(D4:D10) -> 0 | E11: =SUM(E4:E10) -> 0 | F11: =SUM(F4:F10) -> 0 | G11: =SUM(G4:G10) -> 0 | H11: =SUM(H4:H10) -> 0 | I11: =SUM(I4:I10) -> 0 | J11: =SUM(J4:J10) -> 0 | ... L11: =SUM(L4:L10) -> 0 | M11: =SUM(C11:L11) -> 0
A12: 9 | B12: Instant Leaven -450gr | M12: =SUM(C12:L12) -> 0
A13: 10 | B13: Instant Leaven -500gr | M13: =SUM(C13:L13) -> 0
A14: 11 | B14: Leaven Total | C14: =SUM(C12:C13) -> 0 | D14: =SUM(D12:D13) -> 0 | E14: =SUM(E12:E13) -> 0 | F14: =SUM(F12:F13) -> 0 | G14: =SUM(G12:G13) -> 0 | H14: =SUM(H12:H13) -> 0 | I14: =SUM(I12:I13) -> 0 | J14: =SUM(J12:J13) -> 0 | ... L14: =SUM(L12:L13) -> 0 | M14: =SUM(C14:L14) -> 0
A15: 12 | B15: Shortening- 15 kg | M15: =SUM(C15:L15) -> 0
A16: 13 | B16: Total Yest | C16: =C11+C14 -> 0 | D16: =D11+D14 -> 0 | E16: =E11+E14 -> 0 | F16: =F11+F14 -> 0 | G16: =G11+G14 -> 0 | H16: =H11+H14 -> 0 | I16: =I11+I14 -> 0 | J16: =J11+J14 -> 0 | ... L16: =L11+L14 -> 0 | M16: =SUM(C16:L16) -> 0
A17: 14 | B17: Angle Dry Yeast 25g | M17: =SUM(C17:L17) -> 0
A18: 15 | B18: Angle Dry Yeast 50g | M18: =SUM(C18:L18) -> 0
A19: 16 | B19: Total Angle Dry Yeast | C19: =SUM(C17:C18) -> 0 | D19: =SUM(D17:D18) -> 0 | E19: =SUM(E17:E18) -> 0 | F19: =SUM(F17:F18) -> 0 | G19: =SUM(G17:G18) -> 0 | H19: =SUM(H17:H18) -> 0 | I19: =SUM(I17:I18) -> 0 | J19: =SUM(J17:J18) -> 0 | ... M19: =SUM(M17:M18) -> 0
A20: 17 | B20: Mitra Margerine (Bakers compound -15kg) | M20: =SUM(C20:L20) -> 0
A21: 18 | B21: Mitra Margerine (Blue Lable) - 15kg | M21: =SUM(C21:L21) -> 0
A22: 19 | B22: Mitra - (Bun Compound 15Kg) | M22: =SUM(C22:L22) -> 0
A23: 20 | B23: Bakers Star Multy Purpes 15kg | M23: =SUM(C23:L23) -> 0
A24: 21 | B24: Bakers Star Primum Cake 15kg | M24: =SUM(C24:L24) -> 0
A25: 22 | B25: Mitra 15Kg (Bread Compound 15Kg) | M25: =SUM(C25:L25) -> 0
A26: 23 | B26: Bakers Star Pastry Margareen 15kg | M26: =SUM(C26:L26) -> 0
A27: 24 | B27: Bakers Star Creming Fat Margareen 15kg | M27: =SUM(C27:L27) -> 0
A28: 25 | B28: Total Magrgering | C28: =SUM(C20:C27) -> 0 | D28: =SUM(D20:D27) -> 0 | E28: =SUM(E20:E27) -> 0 | F28: =SUM(F20:F27) -> 0 | G28: =SUM(G20:G27) -> 0 | H28: =SUM(H20:H27) -> 0 | I28: =SUM(I20:I27) -> 0 | J28: =SUM(J20:J27) -> 0 | ... L28: =SUM(L20:L27) -> 0 | M28: =SUM(C28:L28) -> 0
A29: 26 | B29: Som-Chai 25kg bag | M29: =SUM(C29:L29) -> 0
A30: 27 | B30: Som-Chai G1 25kg bag | M30: =SUM(C30:L30) -> 0
A31: 28 | B31: Bread Improver- 01kg(LD-500) | M31: =SUM(C31:L31) -> 0
A32: 29 | B32: Bread Improver- 01kg(A-800) | M32: =SUM(C32:L32) -> 0
A33: 30 | B33: Som-Chai G2 25kg bag | M33: =SUM(C33:L33) -> 0
A34: 31 | B34: Som-Chai G2 1kg Pkt | M34: =SUM(C34:L34) -> 0
A35: 32 | B35: Som-Chai G2 350g Pkt | M35: =SUM(C35:L35) -> 0
A36: 33 | B36: Pan Grease- 5L | M36: =SUM(C36:L36) -> 0
A37: 34 | B37: Pan Grease- 20L | M37: =SUM(C37:L37) -> 0
A38: 35 | B38: Hybrid Noodles (Red) | M38: =SUM(C38:L38) -> 0
A39: 36 | B39: Isi PVD 400g | M39: =SUM(C39:L39) -> 0
A40: 37 | B40: Isi 1kg | M40: =SUM(C40:L40) -> 0
...

Sheet 3
A1: Daily achievement sheet (Van/Cluster/Singel /Welimada/DLS Oparations)
A2: Sr | B2: Item Description | M2: ASE
B3: RMS Items | C3: Avissawella | D3: Rathnapura | E3: Hanwella | F3: Horana | G3: Balangoda | H3: Piliyandala | M3: Tatal (B)
A4: 1 | B4: High Sugar- 500gr (Angel) | M4: =SUM(C4:L4) -> 0
A5: 2 | B5: Low Sugar -450gr (Angle) | M5: =SUM(C5:L5) -> 0
A6: 3 | B6: Low Sugar -500gr (Angle) | M6: =SUM(C6:L6) -> 0
A7: 4 | B7: Gloripan Instant Dry Yeast (High Sugar) 500g | M7: =SUM(C7:L7) -> 0
A8: 5 | B8: Gloripan Instant Dry Yeast (Low Sugar) 500g | M8: =SUM(C8:L8) -> 0
A9: 6 | B9: 2 In 1 Yeast 500gr (Low Suger) | M9: =SUM(C9:L9) -> 0
A10: 7 | B10: 2 In 1 Yeast 500gr (High Suger) | M10: =SUM(C10:L10) -> 0
A11: 8 | B11: Bakery Yest total | C11: =SUM(C4:C10) -> 0 | D11: =SUM(D4:D10) -> 0 | E11: =SUM(E4:E10) -> 0 | F11: =SUM(F4:F10) -> 0 | G11: =SUM(G4:G10) -> 0 | H11: =SUM(H4:H10) -> 0 | I11: =SUM(I4:I10) -> 0 | J11: =SUM(J4:J10) -> 0 | ... L11: =SUM(L4:L10) -> 0 | M11: =SUM(C11:L11) -> 0
A12: 9 | B12: Instant Leaven -450gr | M12: =SUM(C12:L12) -> 0
A13: 10 | B13: Instant Leaven -500gr | M13: =SUM(C13:L13) -> 0
A14: 11 | B14: Leaven Total | C14: =SUM(C12:C13) -> 0 | D14: =SUM(D12:D13) -> 0 | E14: =SUM(E12:E13) -> 0 | F14: =SUM(F12:F13) -> 0 | G14: =SUM(G12:G13) -> 0 | H14: =SUM(H12:H13) -> 0 | I14: =SUM(I12:I13) -> 0 | J14: =SUM(J12:J13) -> 0 | ... L14: =SUM(L12:L13) -> 0 | M14: =SUM(C14:L14) -> 0
A15: 12 | B15: Shortening- 15 kg | M15: =SUM(C15:L15) -> 0
A16: 13 | B16: Total Yest | C16: =C11+C14 -> 0 | D16: =D11+D14 -> 0 | E16: =E11+E14 -> 0 | F16: =F11+F14 -> 0 | G16: =G11+G14 -> 0 | H16: =H11+H14 -> 0 | I16: =I11+I14 -> 0 | J16: =J11+J14 -> 0 | ... L16: =L11+L14 -> 0 | M16: =SUM(C16:L16) -> 0
A17: 14 | B17: Angle Dry Yeast 25g | M17: =SUM(C17:L17) -> 0
A18: 15 | B18: Angle Dry Yeast 50g | M18: =SUM(C18:L18) -> 0
A19: 16 | B19: Total Angle Dry Yeast | C19: =SUM(C17:C18) -> 0 | D19: =SUM(D17:D18) -> 0 | E19: =SUM(E17:E18) -> 0 | F19: =SUM(F17:F18) -> 0 | G19: =SUM(G17:G18) -> 0 | H19: =SUM(H17:H18) -> 0 | I19: =SUM(I17:I18) -> 0 | J19: =SUM(J17:J18) -> 0 | ... M19: =SUM(M17:M18) -> 0
A20: 17 | B20: Mitra Margerine (Bakers compound -15kg) | M20: =SUM(C20:L20) -> 0
A21: 18 | B21: Mitra Margerine (Blue Lable) - 15kg | M21: =SUM(C21:L21) -> 0
A22: 19 | B22: Mitra - (Bun Compound 15Kg) | M22: =SUM(C22:L22) -> 0
A23: 20 | B23: Bakers Star Multy Purpes 15kg | M23: =SUM(C23:L23) -> 0
A24: 21 | B24: Bakers Star Primum Cake 15kg | M24: =SUM(C24:L24) -> 0
A25: 22 | B25: Mitra 15Kg (Bread Compound 15Kg) | M25: =SUM(C25:L25) -> 0
A26: 23 | B26: Bakers Star Pastry Margareen 15kg | M26: =SUM(C26:L26) -> 0
A27: 24 | B27: Bakers Star Creming Fat Margareen 15kg | M27: =SUM(C27:L27) -> 0
A28: 25 | B28: Total Magrgering | C28: =SUM(C20:C27) -> 0 | D28: =SUM(D20:D27) -> 0 | E28: =SUM(E20:E27) -> 0 | F28: =SUM(F20:F27) -> 0 | G28: =SUM(G20:G27) -> 0 | H28: =SUM(H20:H27) -> 0 | I28: =SUM(I20:I27) -> 0 | J28: =SUM(J20:J27) -> 0 | ... L28: =SUM(L20:L27) -> 0 | M28: =SUM(C28:L28) -> 0
A29: 26 | B29: Som-Chai 25kg bag | M29: =SUM(C29:L29) -> 0
A30: 27 | B30: Som-Chai G1 25kg bag | M30: =SUM(C30:L30) -> 0
A31: 28 | B31: Bread Improver- 01kg(LD-500) | M31: =SUM(C31:L31) -> 0
A32: 29 | B32: Bread Improver- 01kg(A-800) | M32: =SUM(C32:L32) -> 0
A33: 30 | B33: Som-Chai G2 25kg bag | M33: =SUM(C33:L33) -> 0
A34: 31 | B34: Som-Chai G2 1kg Pkt | M34: =SUM(C34:L34) -> 0
A35: 32 | B35: Som-Chai G2 350g Pkt | M35: =SUM(C35:L35) -> 0
A36: 33 | B36: Pan Grease- 5L | M36: =SUM(C36:L36) -> 0
A37: 34 | B37: Pan Grease- 20L | M37: =SUM(C37:L37) -> 0
A38: 35 | B38: Hybrid Noodles (Red) | M38: =SUM(C38:L38) -> 0
A39: 36 | B39: Isi PVD 400g | M39: =SUM(C39:L39) -> 0
A40: 37 | B40: Isi 1kg | M40: =SUM(C40:L40) -> 0
...

Sheet 4
A1: Daily achievement sheet (Van/Cluster/Singel /Welimada/DLS Oparations)
A2: Sr | B2: Item Description | M2: ASE
B3: RMS Items | C3: Avissawella | D3: Rathnapura | E3: Hanwella | F3: Horana | G3: Balangoda | H3: Piliyandala | M3: Tatal (B)
A4: 1 | B4: High Sugar- 500gr (Angel) | M4: =SUM(C4:L4) -> 0
A5: 2 | B5: Low Sugar -450gr (Angle) | M5: =SUM(C5:L5) -> 0
A6: 3 | B6: Low Sugar -500gr (Angle) | M6: =SUM(C6:L6) -> 0
A7: 4 | B7: Gloripan Instant Dry Yeast (High Sugar) 500g | M7: =SUM(C7:L7) -> 0
A8: 5 | B8: Gloripan Instant Dry Yeast (Low Sugar) 500g | M8: =SUM(C8:L8) -> 0
A9: 6 | B9: 2 In 1 Yeast 500gr (Low Suger) | M9: =SUM(C9:L9) -> 0
A10: 7 | B10: 2 In 1 Yeast 500gr (High Suger) | M10: =SUM(C10:L10) -> 0
A11: 8 | B11: Bakery Yest total | C11: =SUM(C4:C10) -> 0 | D11: =SUM(D4:D10) -> 0 | E11: =SUM(E4:E10) -> 0 | F11: =SUM(F4:F10) -> 0 | G11: =SUM(G4:G10) -> 0 | H11: =SUM(H4:H10) -> 0 | I11: =SUM(I4:I10) -> 0 | J11: =SUM(J4:J10) -> 0 | ... L11: =SUM(L4:L10) -> 0 | M11: =SUM(C11:L11) -> 0
A12: 9 | B12: Instant Leaven -450gr | M12: =SUM(C12:L12) -> 0
A13: 10 | B13: Instant Leaven -500gr | M13: =SUM(C13:L13) -> 0
A14: 11 | B14: Leaven Total | C14: =SUM(C12:C13) -> 0 | D14: =SUM(D12:D13) -> 0 | E14: =SUM(E12:E13) -> 0 | F14: =SUM(F12:F13) -> 0 | G14: =SUM(G12:G13) -> 0 | H14: =SUM(H12:H13) -> 0 | I14: =SUM(I12:I13) -> 0 | J14: =SUM(J12:J13) -> 0 | ... L14: =SUM(L12:L13) -> 0 | M14: =SUM(C14:L14) -> 0
A15: 12 | B15: Shortening- 15 kg | M15: =SUM(C15:L15) -> 0
A16: 13 | B16: Total Yest | C16: =C11+C14 -> 0 | D16: =D11+D14 -> 0 | E16: =E11+E14 -> 0 | F16: =F11+F14 -> 0 | G16: =G11+G14 -> 0 | H16: =H11+H14 -> 0 | I16: =I11+I14 -> 0 | J16: =J11+J14 -> 0 | ... L16: =L11+L14 -> 0 | M16: =SUM(C16:L16) -> 0
A17: 14 | B17: Angle Dry Yeast 25g | M17: =SUM(C17:L17) -> 0
A18: 15 | B18: Angle Dry Yeast 50g | M18: =SUM(C18:L18) -> 0
A19: 16 | B19: Total Angle Dry Yeast | C19: =SUM(C17:C18) -> 0 | D19: =SUM(D17:D18) -> 0 | E19: =SUM(E17:E18) -> 0 | F19: =SUM(F17:F18) -> 0 | G19: =SUM(G17:G18) -> 0 | H19: =SUM(H17:H18) -> 0 | I19: =SUM(I17:I18) -> 0 | J19: =SUM(J17:J18) -> 0 | ... M19: =SUM(M17:M18) -> 0
A20: 17 | B20: Mitra Margerine (Bakers compound -15kg) | M20: =SUM(C20:L20) -> 0
A21: 18 | B21: Mitra Margerine (Blue Lable) - 15kg | M21: =SUM(C21:L21) -> 0
A22: 19 | B22: Mitra - (Bun Compound 15Kg) | M22: =SUM(C22:L22) -> 0
A23: 20 | B23: Bakers Star Multy Purpes 15kg | M23: =SUM(C23:L23) -> 0
A24: 21 | B24: Bakers Star Primum Cake 15kg | M24: =SUM(C24:L24) -> 0
A25: 22 | B25: Mitra 15Kg (Bread Compound 15Kg) | M25: =SUM(C25:L25) -> 0
A26: 23 | B26: Bakers Star Pastry Margareen 15kg | M26: =SUM(C26:L26) -> 0
A27: 24 | B27: Bakers Star Creming Fat Margareen 15kg | M27: =SUM(C27:L27) -> 0
A28: 25 | B28: Total Magrgering | C28: =SUM(C20:C27) -> 0 | D28: =SUM(D20:D27) -> 0 | E28: =SUM(E20:E27) -> 0 | F28: =SUM(F20:F27) -> 0 | G28: =SUM(G20:G27) -> 0 | H28: =SUM(H20:H27) -> 0 | I28: =SUM(I20:I27) -> 0 | J28: =SUM(J20:J27) -> 0 | ... L28: =SUM(L20:L27) -> 0 | M28: =SUM(C28:L28) -> 0
A29: 26 | B29: Som-Chai 25kg bag | M29: =SUM(C29:L29) -> 0
A30: 27 | B30: Som-Chai G1 25kg bag | M30: =SUM(C30:L30) -> 0
A31: 28 | B31: Bread Improver- 01kg(LD-500) | M31: =SUM(C31:L31) -> 0
A32: 29 | B32: Bread Improver- 01kg(A-800) | M32: =SUM(C32:L32) -> 0
A33: 30 | B33: Som-Chai G2 25kg bag | M33: =SUM(C33:L33) -> 0
A34: 31 | B34: Som-Chai G2 1kg Pkt | M34: =SUM(C34:L34) -> 0
A35: 32 | B35: Som-Chai G2 350g Pkt | M35: =SUM(C35:L35) -> 0
A36: 33 | B36: Pan Grease- 5L | M36: =SUM(C36:L36) -> 0
A37: 34 | B37: Pan Grease- 20L | M37: =SUM(C37:L37) -> 0
A38: 35 | B38: Hybrid Noodles (Red) | M38: =SUM(C38:L38) -> 0
A39: 36 | B39: Isi PVD 400g | M39: =SUM(C39:L39) -> 0
A40: 37 | B40: Isi 1kg | M40: =SUM(C40:L40) -> 0
...

Sheet 5
A1: Daily achievement sheet (Van/Cluster/Singel /Welimada/DLS Oparations)
A2: Sr | B2: Item Description | M2: ASE
B3: RMS Items | C3: Avissawella | D3: Rathnapura | E3: Hanwella | F3: Horana | G3: Balangoda | H3: Piliyandala | M3: Tatal (B)
A4: 1 | B4: High Sugar- 500gr (Angel) | M4: =SUM(C4:L4) -> 0
A5: 2 | B5: Low Sugar -450gr (Angle) | M5: =SUM(C5:L5) -> 0
A6: 3 | B6: Low Sugar -500gr (Angle) | M6: =SUM(C6:L6) -> 0
A7: 4 | B7: Gloripan Instant Dry Yeast (High Sugar) 500g | M7: =SUM(C7:L7) -> 0
A8: 5 | B8: Gloripan Instant Dry Yeast (Low Sugar) 500g | M8: =SUM(C8:L8) -> 0
A9: 6 | B9: 2 In 1 Yeast 500gr (Low Suger) | M9: =SUM(C9:L9) -> 0
A10: 7 | B10: 2 In 1 Yeast 500gr (High Suger) | M10: =SUM(C10:L10) -> 0
A11: 8 | B11: Bakery Yest total | C11: =SUM(C4:C10) -> 0 | D11: =SUM(D4:D10) -> 0 | E11: =SUM(E4:E10) -> 0 | F11: =SUM(F4:F10) -> 0 | G11: =SUM(G4:G10) -> 0 | H11: =SUM(H4:H10) -> 0 | I11: =SUM(I4:I10) -> 0 | J11: =SUM(J4:J10) -> 0 | ... L11: =SUM(L4:L10) -> 0 | M11: =SUM(C11:L11) -> 0
A12: 9 | B12: Instant Leaven -450gr | M12: =SUM(C12:L12) -> 0
A13: 10 | B13: Instant Leaven -500gr | M13: =SUM(C13:L13) -> 0
A14: 11 | B14: Leaven Total | C14: =SUM(C12:C13) -> 0 | D14: =SUM(D12:D13) -> 0 | E14: =SUM(E12:E13) -> 0 | F14: =SUM(F12:F13) -> 0 | G14: =SUM(G12:G13) -> 0 | H14: =SUM(H12:H13) -> 0 | I14: =SUM(I12:I13) -> 0 | J14: =SUM(J12:J13) -> 0 | ... L14: =SUM(L12:L13) -> 0 | M14: =SUM(C14:L14) -> 0
A15: 12 | B15: Shortening- 15 kg | M15: =SUM(C15:L15) -> 0
A16: 13 | B16: Total Yest | C16: =C11+C14 -> 0 | D16: =D11+D14 -> 0 | E16: =E11+E14 -> 0 | F16: =F11+F14 -> 0 | G16: =G11+G14 -> 0 | H16: =H11+H14 -> 0 | I16: =I11+I14 -> 0 | J16: =J11+J14 -> 0 | ... L16: =L11+L14 -> 0 | M16: =SUM(C16:L16) -> 0
A17: 14 | B17: Angle Dry Yeast 25g | M17: =SUM(C17:L17) -> 0
A18: 15 | B18: Angle Dry Yeast 50g | M18: =SUM(C18:L18) -> 0
A19: 16 | B19: Total Angle Dry Yeast | C19: =SUM(C17:C18) -> 0 | D19: =SUM(D17:D18) -> 0 | E19: =SUM(E17:E18) -> 0 | F19: =SUM(F17:F18) -> 0 | G19: =SUM(G17:G18) -> 0 | H19: =SUM(H17:H18) -> 0 | I19: =SUM(I17:I18) -> 0 | J19: =SUM(J17:J18) -> 0 | ... M19: =SUM(M17:M18) -> 0
A20: 17 | B20: Mitra Margerine (Bakers compound -15kg) | M20: =SUM(C20:L20) -> 0
A21: 18 | B21: Mitra Margerine (Blue Lable) - 15kg | M21: =SUM(C21:L21) -> 0
A22: 19 | B22: Mitra - (Bun Compound 15Kg) | M22: =SUM(C22:L22) -> 0
A23: 20 | B23: Bakers Star Multy Purpes 15kg | M23: =SUM(C23:L23) -> 0
A24: 21 | B24: Bakers Star Primum Cake 15kg | M24: =SUM(C24:L24) -> 0
A25: 22 | B25: Mitra 15Kg (Bread Compound 15Kg) | M25: =SUM(C25:L25) -> 0
A26: 23 | B26: Bakers Star Pastry Margareen 15kg | M26: =SUM(C26:L26) -> 0
A27: 24 | B27: Bakers Star Creming Fat Margareen 15kg | M27: =SUM(C27:L27) -> 0
A28: 25 | B28: Total Magrgering | C28: =SUM(C20:C27) -> 0 | D28: =SUM(D20:D27) -> 0 | E28: =SUM(E20:E27) -> 0 | F28: =SUM(F20:F27) -> 0 | G28: =SUM(G20:G27) -> 0 | H28: =SUM(H20:H27) -> 0 | I28: =SUM(I20:I27) -> 0 | J28: =SUM(J20:J27) -> 0 | ... L28: =SUM(L20:L27) -> 0 | M28: =SUM(C28:L28) -> 0
A29: 26 | B29: Som-Chai 25kg bag | M29: =SUM(C29:L29) -> 0
A30: 27 | B30: Som-Chai G1 25kg bag | M30: =SUM(C30:L30) -> 0
A31: 28 | B31: Bread Improver- 01kg(LD-500) | M31: =SUM(C31:L31) -> 0
A32: 29 | B32: Bread Improver- 01kg(A-800) | M32: =SUM(C32:L32) -> 0
A33: 30 | B33: Som-Chai G2 25kg bag | M33: =SUM(C33:L33) -> 0
A34: 31 | B34: Som-Chai G2 1kg Pkt | M34: =SUM(C34:L34) -> 0
A35: 32 | B35: Som-Chai G2 350g Pkt | M35: =SUM(C35:L35) -> 0
A36: 33 | B36: Pan Grease- 5L | M36: =SUM(C36:L36) -> 0
A37: 34 | B37: Pan Grease- 20L | M37: =SUM(C37:L37) -> 0
A38: 35 | B38: Hybrid Noodles (Red) | M38: =SUM(C38:L38) -> 0
A39: 36 | B39: Isi PVD 400g | M39: =SUM(C39:L39) -> 0
A40: 37 | B40: Isi 1kg | M40: =SUM(C40:L40) -> 0
...

Sheet 6
A1: Daily achievement sheet (Van/Cluster/Singel /Welimada/DLS Oparations)
A2: Sr | B2: Item Description | M2: ASE
B3: RMS Items | C3: Avissawella | D3: Rathnapura | E3: Hanwella | F3: Horana | G3: Balangoda | H3: Piliyandala | M3: Tatal (B)
A4: 1 | B4: High Sugar- 500gr (Angel) | M4: =SUM(C4:L4) -> 0
A5: 2 | B5: Low Sugar -450gr (Angle) | M5: =SUM(C5:L5) -> 0
A6: 3 | B6: Low Sugar -500gr (Angle) | M6: =SUM(C6:L6) -> 0
A7: 4 | B7: Gloripan Instant Dry Yeast (High Sugar) 500g | M7: =SUM(C7:L7) -> 0
A8: 5 | B8: Gloripan Instant Dry Yeast (Low Sugar) 500g | M8: =SUM(C8:L8) -> 0
A9: 6 | B9: 2 In 1 Yeast 500gr (Low Suger) | M9: =SUM(C9:L9) -> 0
A10: 7 | B10: 2 In 1 Yeast 500gr (High Suger) | M10: =SUM(C10:L10) -> 0
A11: 8 | B11: Bakery Yest total | C11: =SUM(C4:C10) -> 0 | D11: =SUM(D4:D10) -> 0 | E11: =SUM(E4:E10) -> 0 | F11: =SUM(F4:F10) -> 0 | G11: =SUM(G4:G10) -> 0 | H11: =SUM(H4:H10) -> 0 | I11: =SUM(I4:I10) -> 0 | J11: =SUM(J4:J10) -> 0 | ... L11: =SUM(L4:L10) -> 0 | M11: =SUM(C11:L11) -> 0
A12: 9 | B12: Instant Leaven -450gr | M12: =SUM(C12:L12) -> 0
A13: 10 | B13: Instant Leaven -500gr | M13: =SUM(C13:L13) -> 0
A14: 11 | B14: Leaven Total | C14: =SUM(C12:C13) -> 0 | D14: =SUM(D12:D13) -> 0 | E14: =SUM(E12:E13) -> 0 | F14: =SUM(F12:F13) -> 0 | G14: =SUM(G12:G13) -> 0 | H14: =SUM(H12:H13) -> 0 | I14: =SUM(I12:I13) -> 0 | J14: =SUM(J12:J13) -> 0 | ... L14: =SUM(L12:L13) -> 0 | M14: =SUM(C14:L14) -> 0
A15: 12 | B15: Shortening- 15 kg | M15: =SUM(C15:L15) -> 0
A16: 13 | B16: Total Yest | C16: =C11+C14 -> 0 | D16: =D11+D14 -> 0 | E16: =E11+E14 -> 0 | F16: =F11+F14 -> 0 | G16: =G11+G14 -> 0 | H16: =H11+H14 -> 0 | I16: =I11+I14 -> 0 | J16: =J11+J14 -> 0 | ... L16: =L11+L14 -> 0 | M16: =SUM(C16:L16) -> 0
A17: 14 | B17: Angle Dry Yeast 25g | M17: =SUM(C17:L17) -> 0
A18: 15 | B18: Angle Dry Yeast 50g | M18: =SUM(C18:L18) -> 0
A19: 16 | B19: Total Angle Dry Yeast | C19: =SUM(C17:C18) -> 0 | D19: =SUM(D17:D18) -> 0 | E19: =SUM(E17:E18) -> 0 | F19: =SUM(F17:F18) -> 0 | G19: =SUM(G17:G18) -> 0 | H19: =SUM(H17:H18) -> 0 | I19: =SUM(I17:I18) -> 0 | J19: =SUM(J17:J18) -> 0 | ... M19: =SUM(M17:M18) -> 0
A20: 17 | B20: Mitra Margerine (Bakers compound -15kg) | M20: =SUM(C20:L20) -> 0
A21: 18 | B21: Mitra Margerine (Blue Lable) - 15kg | M21: =SUM(C21:L21) -> 0
A22: 19 | B22: Mitra - (Bun Compound 15Kg) | M22: =SUM(C22:L22) -> 0
A23: 20 | B23: Bakers Star Multy Purpes 15kg | M23: =SUM(C23:L23) -> 0
A24: 21 | B24: Bakers Star Primum Cake 15kg | M24: =SUM(C24:L24) -> 0
A25: 22 | B25: Mitra 15Kg (Bread Compound 15Kg) | M25: =SUM(C25:L25) -> 0
A26: 23 | B26: Bakers Star Pastry Margareen 15kg | M26: =SUM(C26:L26) -> 0
A27: 24 | B27: Bakers Star Creming Fat Margareen 15kg | M27: =SUM(C27:L27) -> 0
A28: 25 | B28: Total Magrgering | C28: =SUM(C20:C27) -> 0 | D28: =SUM(D20:D27) -> 0 | E28: =SUM(E20:E27) -> 0 | F28: =SUM(F20:F27) -> 0 | G28: =SUM(G20:G27) -> 0 | H28: =SUM(H20:H27) -> 0 | I28: =SUM(I20:I27) -> 0 | J28: =SUM(J20:J27) -> 0 | ... L28: =SUM(L20:L27) -> 0 | M28: =SUM(C28:L28) -> 0
A29: 26 | B29: Som-Chai 25kg bag | M29: =SUM(C29:L29) -> 0
A30: 27 | B30: Som-Chai G1 25kg bag | M30: =SUM(C30:L30) -> 0
A31: 28 | B31: Bread Improver- 01kg(LD-500) | M31: =SUM(C31:L31) -> 0
A32: 29 | B32: Bread Improver- 01kg(A-800) | M32: =SUM(C32:L32) -> 0
A33: 30 | B33: Som-Chai G2 25kg bag | M33: =SUM(C33:L33) -> 0
A34: 31 | B34: Som-Chai G2 1kg Pkt | M34: =SUM(C34:L34) -> 0
A35: 32 | B35: Som-Chai G2 350g Pkt | M35: =SUM(C35:L35) -> 0
A36: 33 | B36: Pan Grease- 5L | M36: =SUM(C36:L36) -> 0
A37: 34 | B37: Pan Grease- 20L | M37: =SUM(C37:L37) -> 0
A38: 35 | B38: Hybrid Noodles (Red) | M38: =SUM(C38:L38) -> 0
A39: 36 | B39: Isi PVD 400g | M39: =SUM(C39:L39) -> 0
A40: 37 | B40: Isi 1kg | M40: =SUM(C40:L40) -> 0
...

Sheet 7
A1: Daily achievement sheet (Van/Cluster/Singel /Welimada/DLS Oparations)
A2: Sr | B2: Item Description | M2: ASE
B3: RMS Items | C3: Avissawella | D3: Rathnapura | E3: Hanwella | F3: Horana | G3: Balangoda | H3: Piliyandala | M3: Tatal (B)
A4: 1 | B4: High Sugar- 500gr (Angel) | M4: =SUM(C4:L4) -> 0
A5: 2 | B5: Low Sugar -450gr (Angle) | M5: =SUM(C5:L5) -> 0
A6: 3 | B6: Low Sugar -500gr (Angle) | M6: =SUM(C6:L6) -> 0
A7: 4 | B7: Gloripan Instant Dry Yeast (High Sugar) 500g | M7: =SUM(C7:L7) -> 0
A8: 5 | B8: Gloripan Instant Dry Yeast (Low Sugar) 500g | M8: =SUM(C8:L8) -> 0
A9: 6 | B9: 2 In 1 Yeast 500gr (Low Suger) | M9: =SUM(C9:L9) -> 0
A10: 7 | B10: 2 In 1 Yeast 500gr (High Suger) | M10: =SUM(C10:L10) -> 0
A11: 8 | B11: Bakery Yest total | C11: =SUM(C4:C10) -> 0 | D11: =SUM(D4:D10) -> 0 | E11: =SUM(E4:E10) -> 0 | F11: =SUM(F4:F10) -> 0 | G11: =SUM(G4:G10) -> 0 | H11: =SUM(H4:H10) -> 0 | I11: =SUM(I4:I10) -> 0 | J11: =SUM(J4:J10) -> 0 | ... L11: =SUM(L4:L10) -> 0 | M11: =SUM(C11:L11) -> 0
A12: 9 | B12: Instant Leaven -450gr | M12: =SUM(C12:L12) -> 0
A13: 10 | B13: Instant Leaven -500gr | M13: =SUM(C13:L13) -> 0
A14: 11 | B14: Leaven Total | C14: =SUM(C12:C13) -> 0 | D14: =SUM(D12:D13) -> 0 | E14: =SUM(E12:E13) -> 0 | F14: =SUM(F12:F13) -> 0 | G14: =SUM(G12:G13) -> 0 | H14: =SUM(H12:H13) -> 0 | I14: =SUM(I12:I13) -> 0 | J14: =SUM(J12:J13) -> 0 | ... L14: =SUM(L12:L13) -> 0 | M14: =SUM(C14:L14) -> 0
A15: 12 | B15: Shortening- 15 kg | M15: =SUM(C15:L15) -> 0
A16: 13 | B16: Total Yest | C16: =C11+C14 -> 0 | D16: =D11+D14 -> 0 | E16: =E11+E14 -> 0 | F16: =F11+F14 -> 0 | G16: =G11+G14 -> 0 | H16: =H11+H14 -> 0 | I16: =I11+I14 -> 0 | J16: =J11+J14 -> 0 | ... L16: =L11+L14 -> 0 | M16: =SUM(C16:L16) -> 0
A17: 14 | B17: Angle Dry Yeast 25g | M17: =SUM(C17:L17) -> 0
A18: 15 | B18: Angle Dry Yeast 50g | M18: =SUM(C18:L18) -> 0
A19: 16 | B19: Total Angle Dry Yeast | C19: =SUM(C17:C18) -> 0 | D19: =SUM(D17:D18) -> 0 | E19: =SUM(E17:E18) -> 0 | F19: =SUM(F17:F18) -> 0 | G19: =SUM(G17:G18) -> 0 | H19: =SUM(H17:H18) -> 0 | I19: =SUM(I17:I18) -> 0 | J19: =SUM(J17:J18) -> 0 | ... M19: =SUM(M17:M18) -> 0
A20: 17 | B20: Mitra Margerine (Bakers compound -15kg) | M20: =SUM(C20:L20) -> 0
A21: 18 | B21: Mitra Margerine (Blue Lable) - 15kg | M21: =SUM(C21:L21) -> 0
A22: 19 | B22: Mitra - (Bun Compound 15Kg) | M22: =SUM(C22:L22) -> 0
A23: 20 | B23: Bakers Star Multy Purpes 15kg | M23: =SUM(C23:L23) -> 0
A24: 21 | B24: Bakers Star Primum Cake 15kg | M24: =SUM(C24:L24) -> 0
A25: 22 | B25: Mitra 15Kg (Bread Compound 15Kg) | M25: =SUM(C25:L25) -> 0
A26: 23 | B26: Bakers Star Pastry Margareen 15kg | M26: =SUM(C26:L26) -> 0
A27: 24 | B27: Bakers Star Creming Fat Margareen 15kg | M27: =SUM(C27:L27) -> 0
A28: 25 | B28: Total Magrgering | C28: =SUM(C20:C27) -> 0 | D28: =SUM(D20:D27) -> 0 | E28: =SUM(E20:E27) -> 0 | F28: =SUM(F20:F27) -> 0 | G28: =SUM(G20:G27) -> 0 | H28: =SUM(H20:H27) -> 0 | I28: =SUM(I20:I27) -> 0 | J28: =SUM(J20:J27) -> 0 | ... L28: =SUM(L20:L27) -> 0 | M28: =SUM(C28:L28) -> 0
A29: 26 | B29: Som-Chai 25kg bag | M29: =SUM(C29:L29) -> 0
A30: 27 | B30: Som-Chai G1 25kg bag | M30: =SUM(C30:L30) -> 0
A31: 28 | B31: Bread Improver- 01kg(LD-500) | M31: =SUM(C31:L31) -> 0
A32: 29 | B32: Bread Improver- 01kg(A-800) | M32: =SUM(C32:L32) -> 0
A33: 30 | B33: Som-Chai G2 25kg bag | M33: =SUM(C33:L33) -> 0
A34: 31 | B34: Som-Chai G2 1kg Pkt | M34: =SUM(C34:L34) -> 0
A35: 32 | B35: Som-Chai G2 350g Pkt | M35: =SUM(C35:L35) -> 0
A36: 33 | B36: Pan Grease- 5L | M36: =SUM(C36:L36) -> 0
A37: 34 | B37: Pan Grease- 20L | M37: =SUM(C37:L37) -> 0
A38: 35 | B38: Hybrid Noodles (Red) | M38: =SUM(C38:L38) -> 0
A39: 36 | B39: Isi PVD 400g | M39: =SUM(C39:L39) -> 0
A40: 37 | B40: Isi 1kg | M40: =SUM(C40:L40) -> 0
...

Sheet 8
A1: Daily achievement sheet (Van/Cluster/Singel /Welimada/DLS Oparations)
A2: Sr | B2: Item Description | M2: ASE
B3: RMS Items | C3: Avissawella | D3: Rathnapura | E3: Hanwella | F3: Horana | G3: Balangoda | H3: Piliyandala | M3: Tatal (B)
A4: 1 | B4: High Sugar- 500gr (Angel) | M4: =SUM(C4:L4) -> 0
A5: 2 | B5: Low Sugar -450gr (Angle) | M5: =SUM(C5:L5) -> 0
A6: 3 | B6: Low Sugar -500gr (Angle) | M6: =SUM(C6:L6) -> 0
A7: 4 | B7: Gloripan Instant Dry Yeast (High Sugar) 500g | M7: =SUM(C7:L7) -> 0
A8: 5 | B8: Gloripan Instant Dry Yeast (Low Sugar) 500g | M8: =SUM(C8:L8) -> 0
A9: 6 | B9: 2 In 1 Yeast 500gr (Low Suger) | M9: =SUM(C9:L9) -> 0
A10: 7 | B10: 2 In 1 Yeast 500gr (High Suger) | M10: =SUM(C10:L10) -> 0
A11: 8 | B11: Bakery Yest total | C11: =SUM(C4:C10) -> 0 | D11: =SUM(D4:D10) -> 0 | E11: =SUM(E4:E10) -> 0 | F11: =SUM(F4:F10) -> 0 | G11: =SUM(G4:G10) -> 0 | H11: =SUM(H4:H10) -> 0 | I11: =SUM(I4:I10) -> 0 | J11: =SUM(J4:J10) -> 0 | ... L11: =SUM(L4:L10) -> 0 | M11: =SUM(C11:L11) -> 0
A12: 9 | B12: Instant Leaven -450gr | M12: =SUM(C12:L12) -> 0
A13: 10 | B13: Instant Leaven -500gr | M13: =SUM(C13:L13) -> 0
A14: 11 | B14: Leaven Total | C14: =SUM(C12:C13) -> 0 | D14: =SUM(D12:D13) -> 0 | E14: =SUM(E12:E13) -> 0 | F14: =SUM(F12:F13) -> 0 | G14: =SUM(G12:G13) -> 0 | H14: =SUM(H12:H13) -> 0 | I14: =SUM(I12:I13) -> 0 | J14: =SUM(J12:J13) -> 0 | ... L14: =SUM(L12:L13) -> 0 | M14: =SUM(C14:L14) -> 0
A15: 12 | B15: Shortening- 15 kg | M15: =SUM(C15:L15) -> 0
A16: 13 | B16: Total Yest | C16: =C11+C14 -> 0 | D16: =D11+D14 -> 0 | E16: =E11+E14 -> 0 | F16: =F11+F14 -> 0 | G16: =G11+G14 -> 0 | H16: =H11+H14 -> 0 | I16: =I11+I14 -> 0 | J16: =J11+J14 -> 0 | ... L16: =L11+L14 -> 0 | M16: =SUM(C16:L16) -> 0
A17: 14 | B17: Angle Dry Yeast 25g | M17: =SUM(C17:L17) -> 0
A18: 15 | B18: Angle Dry Yeast 50g | M18: =SUM(C18:L18) -> 0
A19: 16 | B19: Total Angle Dry Yeast | C19: =SUM(C17:C18) -> 0 | D19: =SUM(D17:D18) -> 0 | E19: =SUM(E17:E18) -> 0 | F19: =SUM(F17:F18) -> 0 | G19: =SUM(G17:G18) -> 0 | H19: =SUM(H17:H18) -> 0 | I19: =SUM(I17:I18) -> 0 | J19: =SUM(J17:J18) -> 0 | ... M19: =SUM(M17:M18) -> 0
A20: 17 | B20: Mitra Margerine (Bakers compound -15kg) | M20: =SUM(C20:L20) -> 0
A21: 18 | B21: Mitra Margerine (Blue Lable) - 15kg | M21: =SUM(C21:L21) -> 0
A22: 19 | B22: Mitra - (Bun Compound 15Kg) | M22: =SUM(C22:L22) -> 0
A23: 20 | B23: Bakers Star Multy Purpes 15kg | M23: =SUM(C23:L23) -> 0
A24: 21 | B24: Bakers Star Primum Cake 15kg | M24: =SUM(C24:L24) -> 0
A25: 22 | B25: Mitra 15Kg (Bread Compound 15Kg) | M25: =SUM(C25:L25) -> 0
A26: 23 | B26: Bakers Star Pastry Margareen 15kg | M26: =SUM(C26:L26) -> 0
A27: 24 | B27: Bakers Star Creming Fat Margareen 15kg | M27: =SUM(C27:L27) -> 0
A28: 25 | B28: Total Magrgering | C28: =SUM(C20:C27) -> 0 | D28: =SUM(D20:D27) -> 0 | E28: =SUM(E20:E27) -> 0 | F28: =SUM(F20:F27) -> 0 | G28: =SUM(G20:G27) -> 0 | H28: =SUM(H20:H27) -> 0 | I28: =SUM(I20:I27) -> 0 | J28: =SUM(J20:J27) -> 0 | ... L28: =SUM(L20:L27) -> 0 | M28: =SUM(C28:L28) -> 0
A29: 26 | B29: Som-Chai 25kg bag | M29: =SUM(C29:L29) -> 0
A30: 27 | B30: Som-Chai G1 25kg bag | M30: =SUM(C30:L30) -> 0
A31: 28 | B31: Bread Improver- 01kg(LD-500) | M31: =SUM(C31:L31) -> 0
A32: 29 | B32: Bread Improver- 01kg(A-800) | M32: =SUM(C32:L32) -> 0
A33: 30 | B33: Som-Chai G2 25kg bag | M33: =SUM(C33:L33) -> 0
A34: 31 | B34: Som-Chai G2 1kg Pkt | M34: =SUM(C34:L34) -> 0
A35: 32 | B35: Som-Chai G2 350g Pkt | M35: =SUM(C35:L35) -> 0
A36: 33 | B36: Pan Grease- 5L | M36: =SUM(C36:L36) -> 0
A37: 34 | B37: Pan Grease- 20L | M37: =SUM(C37:L37) -> 0
A38: 35 | B38: Hybrid Noodles (Red) | M38: =SUM(C38:L38) -> 0
A39: 36 | B39: Isi PVD 400g | M39: =SUM(C39:L39) -> 0
A40: 37 | B40: Isi 1kg | M40: =SUM(C40:L40) -> 0
...

Sheet 9
A1: Daily achievement sheet (Van/Cluster/Singel /Welimada/DLS Oparations)
A2: Sr | B2: Item Description | M2: ASE
B3: RMS Items | C3: Avissawella | D3: Rathnapura | E3: Hanwella | F3: Horana | G3: Balangoda | H3: Piliyandala | M3: Tatal (B)
A4: 1 | B4: High Sugar- 500gr (Angel) | M4: =SUM(C4:L4) -> 0
A5: 2 | B5: Low Sugar -450gr (Angle) | M5: =SUM(C5:L5) -> 0
A6: 3 | B6: Low Sugar -500gr (Angle) | M6: =SUM(C6:L6) -> 0
A7: 4 | B7: Gloripan Instant Dry Yeast (High Sugar) 500g | M7: =SUM(C7:L7) -> 0
A8: 5 | B8: Gloripan Instant Dry Yeast (Low Sugar) 500g | M8: =SUM(C8:L8) -> 0
A9: 6 | B9: 2 In 1 Yeast 500gr (Low Suger) | M9: =SUM(C9:L9) -> 0
A10: 7 | B10: 2 In 1 Yeast 500gr (High Suger) | M10: =SUM(C10:L10) -> 0
A11: 8 | B11: Bakery Yest total | C11: =SUM(C4:C10) -> 0 | D11: =SUM(D4:D10) -> 0 | E11: =SUM(E4:E10) -> 0 | F11: =SUM(F4:F10) -> 0 | G11: =SUM(G4:G10) -> 0 | H11: =SUM(H4:H10) -> 0 | I11: =SUM(I4:I10) -> 0 | J11: =SUM(J4:J10) -> 0 | ... L11: =SUM(L4:L10) -> 0 | M11: =SUM(C11:L11) -> 0
A12: 9 | B12: Instant Leaven -450gr | M12: =SUM(C12:L12) -> 0
A13: 10 | B13: Instant Leaven -500gr | M13: =SUM(C13:L13) -> 0
A14: 11 | B14: Leaven Total | C14: =SUM(C12:C13) -> 0 | D14: =SUM(D12:D13) -> 0 | E14: =SUM(E12:E13) -> 0 | F14: =SUM(F12:F13) -> 0 | G14: =SUM(G12:G13) -> 0 | H14: =SUM(H12:H13) -> 0 | I14: =SUM(I12:I13) -> 0 | J14: =SUM(J12:J13) -> 0 | ... L14: =SUM(L12:L13) -> 0 | M14: =SUM(C14:L14) -> 0
A15: 12 | B15: Shortening- 15 kg | M15: =SUM(C15:L15) -> 0
A16: 13 | B16: Total Yest | C16: =C11+C14 -> 0 | D16: =D11+D14 -> 0 | E16: =E11+E14 -> 0 | F16: =F11+F14 -> 0 | G16: =G11+G14 -> 0 | H16: =H11+H14 -> 0 | I16: =I11+I14 -> 0 | J16: =J11+J14 -> 0 | ... L16: =L11+L14 -> 0 | M16: =SUM(C16:L16) -> 0
A17: 14 | B17: Angle Dry Yeast 25g | M17: =SUM(C17:L17) -> 0
A18: 15 | B18: Angle Dry Yeast 50g | M18: =SUM(C18:L18) -> 0
A19: 16 | B19: Total Angle Dry Yeast | C19: =SUM(C17:C18) -> 0 | D19: =SUM(D17:D18) -> 0 | E19: =SUM(E17:E18) -> 0 | F19: =SUM(F17:F18) -> 0 | G19: =SUM(G17:G18) -> 0 | H19: =SUM(H17:H18) -> 0 | I19: =SUM(I17:I18) -> 0 | J19: =SUM(J17:J18) -> 0 | ... M19: =SUM(M17:M18) -> 0
A20: 17 | B20: Mitra Margerine (Bakers compound -15kg) | M20: =SUM(C20:L20) -> 0
A21: 18 | B21: Mitra Margerine (Blue Lable) - 15kg | M21: =SUM(C21:L21) -> 0
A22: 19 | B22: Mitra - (Bun Compound 15Kg) | M22: =SUM(C22:L22) -> 0
A23: 20 | B23: Bakers Star Multy Purpes 15kg | M23: =SUM(C23:L23) -> 0
A24: 21 | B24: Bakers Star Primum Cake 15kg | M24: =SUM(C24:L24) -> 0
A25: 22 | B25: Mitra 15Kg (Bread Compound 15Kg) | M25: =SUM(C25:L25) -> 0
A26: 23 | B26: Bakers Star Pastry Margareen 15kg | M26: =SUM(C26:L26) -> 0
A27: 24 | B27: Bakers Star Creming Fat Margareen 15kg | M27: =SUM(C27:L27) -> 0
A28: 25 | B28: Total Magrgering | C28: =SUM(C20:C27) -> 0 | D28: =SUM(D20:D27) -> 0 | E28: =SUM(E20:E27) -> 0 | F28: =SUM(F20:F27) -> 0 | G28: =SUM(G20:G27) -> 0 | H28: =SUM(H20:H27) -> 0 | I28: =SUM(I20:I27) -> 0 | J28: =SUM(J20:J27) -> 0 | ... L28: =SUM(L20:L27) -> 0 | M28: =SUM(C28:L28) -> 0
A29: 26 | B29: Som-Chai 25kg bag | M29: =SUM(C29:L29) -> 0
A30: 27 | B30: Som-Chai G1 25kg bag | M30: =SUM(C30:L30) -> 0
A31: 28 | B31: Bread Improver- 01kg(LD-500) | M31: =SUM(C31:L31) -> 0
A32: 29 | B32: Bread Improver- 01kg(A-800) | M32: =SUM(C32:L32) -> 0
A33: 30 | B33: Som-Chai G2 25kg bag | M33: =SUM(C33:L33) -> 0
A34: 31 | B34: Som-Chai G2 1kg Pkt | M34: =SUM(C34:L34) -> 0
A35: 32 | B35: Som-Chai G2 350g Pkt | M35: =SUM(C35:L35) -> 0
A36: 33 | B36: Pan Grease- 5L | M36: =SUM(C36:L36) -> 0
A37: 34 | B37: Pan Grease- 20L | M37: =SUM(C37:L37) -> 0
A38: 35 | B38: Hybrid Noodles (Red) | M38: =SUM(C38:L38) -> 0
A39: 36 | B39: Isi PVD 400g | M39: =SUM(C39:L39) -> 0
A40: 37 | B40: Isi 1kg | M40: =SUM(C40:L40) -> 0
...

Sheet 10
A1: Daily achievement sheet (Van/Cluster/Singel /Welimada/DLS Oparations)
A2: Sr | B2: Item Description | M2: ASE
B3: RMS Items | C3: Avissawella | D3: Rathnapura | E3: Hanwella | F3: Horana | G3: Balangoda | H3: Piliyandala | M3: Tatal (B)
A4: 1 | B4: High Sugar- 500gr (Angel) | M4: =SUM(C4:L4) -> 0
A5: 2 | B5: Low Sugar -450gr (Angle) | M5: =SUM(C5:L5) -> 0
A6: 3 | B6: Low Sugar -500gr (Angle) | M6: =SUM(C6:L6) -> 0
A7: 4 | B7: Gloripan Instant Dry Yeast (High Sugar) 500g | M7: =SUM(C7:L7) -> 0
A8: 5 | B8: Gloripan Instant Dry Yeast (Low Sugar) 500g | M8: =SUM(C8:L8) -> 0
A9: 6 | B9: 2 In 1 Yeast 500gr (Low Suger) | M9: =SUM(C9:L9) -> 0
A10: 7 | B10: 2 In 1 Yeast 500gr (High Suger) | M10: =SUM(C10:L10) -> 0
A11: 8 | B11: Bakery Yest total | C11: =SUM(C4:C10) -> 0 | D11: =SUM(D4:D10) -> 0 | E11: =SUM(E4:E10) -> 0 | F11: =SUM(F4:F10) -> 0 | G11: =SUM(G4:G10) -> 0 | H11: =SUM(H4:H10) -> 0 | I11: =SUM(I4:I10) -> 0 | J11: =SUM(J4:J10) -> 0 | ... L11: =SUM(L4:L10) -> 0 | M11: =SUM(C11:L11) -> 0
A12: 9 | B12: Instant Leaven -450gr | M12: =SUM(C12:L12) -> 0
A13: 10 | B13: Instant Leaven -500gr | M13: =SUM(C13:L13) -> 0
A14: 11 | B14: Leaven Total | C14: =SUM(C12:C13) -> 0 | D14: =SUM(D12:D13) -> 0 | E14: =SUM(E12:E13) -> 0 | F14: =SUM(F12:F13) -> 0 | G14: =SUM(G12:G13) -> 0 | H14: =SUM(H12:H13) -> 0 | I14: =SUM(I12:I13) -> 0 | J14: =SUM(J12:J13) -> 0 | ... L14: =SUM(L12:L13) -> 0 | M14: =SUM(C14:L14) -> 0
A15: 12 | B15: Shortening- 15 kg | M15: =SUM(C15:L15) -> 0
A16: 13 | B16: Total Yest | C16: =C11+C14 -> 0 | D16: =D11+D14 -> 0 | E16: =E11+E14 -> 0 | F16: =F11+F14 -> 0 | G16: =G11+G14 -> 0 | H16: =H11+H14 -> 0 | I16: =I11+I14 -> 0 | J16: =J11+J14 -> 0 | ... L16: =L11+L14 -> 0 | M16: =SUM(C16:L16) -> 0
A17: 14 | B17: Angle Dry Yeast 25g | M17: =SUM(C17:L17) -> 0
A18: 15 | B18: Angle Dry Yeast 50g | M18: =SUM(C18:L18) -> 0
A19: 16 | B19: Total Angle Dry Yeast | C19: =SUM(C17:C18) -> 0 | D19: =SUM(D17:D18) -> 0 | E19: =SUM(E17:E18) -> 0 | F19: =SUM(F17:F18) -> 0 | G19: =SUM(G17:G18) -> 0 | H19: =SUM(H17:H18) -> 0 | I19: =SUM(I17:I18) -> 0 | J19: =SUM(J17:J18) -> 0 | ... M19: =SUM(M17:M18) -> 0
A20: 17 | B20: Mitra Margerine (Bakers compound -15kg) | M20: =SUM(C20:L20) -> 0
A21: 18 | B21: Mitra Margerine (Blue Lable) - 15kg | M21: =SUM(C21:L21) -> 0
A22: 19 | B22: Mitra - (Bun Compound 15Kg) | M22: =SUM(C22:L22) -> 0
A23: 20 | B23: Bakers Star Multy Purpes 15kg | M23: =SUM(C23:L23) -> 0
A24: 21 | B24: Bakers Star Primum Cake 15kg | M24: =SUM(C24:L24) -> 0
A25: 22 | B25: Mitra 15Kg (Bread Compound 15Kg) | M25: =SUM(C25:L25) -> 0
A26: 23 | B26: Bakers Star Pastry Margareen 15kg | M26: =SUM(C26:L26) -> 0
A27: 24 | B27: Bakers Star Creming Fat Margareen 15kg | M27: =SUM(C27:L27) -> 0
A28: 25 | B28: Total Magrgering | C28: =SUM(C20:C27) -> 0 | D28: =SUM(D20:D27) -> 0 | E28: =SUM(E20:E27) -> 0 | F28: =SUM(F20:F27) -> 0 | G28: =SUM(G20:G27) -> 0 | H28: =SUM(H20:H27) -> 0 | I28: =SUM(I20:I27) -> 0 | J28: =SUM(J20:J27) -> 0 | ... L28: =SUM(L20:L27) -> 0 | M28: =SUM(C28:L28) -> 0
A29: 26 | B29: Som-Chai 25kg bag | M29: =SUM(C29:L29) -> 0
A30: 27 | B30: Som-Chai G1 25kg bag | M30: =SUM(C30:L30) -> 0
A31: 28 | B31: Bread Improver- 01kg(LD-500) | M31: =SUM(C31:L31) -> 0
A32: 29 | B32: Bread Improver- 01kg(A-800) | M32: =SUM(C32:L32) -> 0
A33: 30 | B33: Som-Chai G2 25kg bag | M33: =SUM(C33:L33) -> 0
A34: 31 | B34: Som-Chai G2 1kg Pkt | M34: =SUM(C34:L34) -> 0
A35: 32 | B35: Som-Chai G2 350g Pkt | M35: =SUM(C35:L35) -> 0
A36: 33 | B36: Pan Grease- 5L | M36: =SUM(C36:L36) -> 0
A37: 34 | B37: Pan Grease- 20L | M37: =SUM(C37:L37) -> 0
A38: 35 | B38: Hybrid Noodles (Red) | M38: =SUM(C38:L38) -> 0
A39: 36 | B39: Isi PVD 400g | M39: =SUM(C39:L39) -> 0
A40: 37 | B40: Isi 1kg | M40: =SUM(C40:L40) -> 0
...

Sheet 11
A1: Daily achievement sheet (Van/Cluster/Singel /Welimada/DLS Oparations)
A2: Sr | B2: Item Description | M2: ASE
B3: RMS Items | C3: Avissawella | D3: Rathnapura | E3: Hanwella | F3: Horana | G3: Balangoda | H3: Piliyandala | M3: Tatal (B)
A4: 1 | B4: High Sugar- 500gr (Angel) | M4: =SUM(C4:L4) -> 0
A5: 2 | B5: Low Sugar -450gr (Angle) | M5: =SUM(C5:L5) -> 0
A6: 3 | B6: Low Sugar -500gr (Angle) | M6: =SUM(C6:L6) -> 0
A7: 4 | B7: Gloripan Instant Dry Yeast (High Sugar) 500g | M7: =SUM(C7:L7) -> 0
A8: 5 | B8: Gloripan Instant Dry Yeast (Low Sugar) 500g | M8: =SUM(C8:L8) -> 0
A9: 6 | B9: 2 In 1 Yeast 500gr (Low Suger) | M9: =SUM(C9:L9) -> 0
A10: 7 | B10: 2 In 1 Yeast 500gr (High Suger) | M10: =SUM(C10:L10) -> 0
A11: 8 | B11: Bakery Yest total | C11: =SUM(C4:C10) -> 0 | D11: =SUM(D4:D10) -> 0 | E11: =SUM(E4:E10) -> 0 | F11: =SUM(F4:F10) -> 0 | G11: =SUM(G4:G10) -> 0 | H11: =SUM(H4:H10) -> 0 | I11: =SUM(I4:I10) -> 0 | J11: =SUM(J4:J10) -> 0 | ... L11: =SUM(L4:L10) -> 0 | M11: =SUM(C11:L11) -> 0
A12: 9 | B12: Instant Leaven -450gr | M12: =SUM(C12:L12) -> 0
A13: 10 | B13: Instant Leaven -500gr | M13: =SUM(C13:L13) -> 0
A14: 11 | B14: Leaven Total | C14: =SUM(C12:C13) -> 0 | D14: =SUM(D12:D13) -> 0 | E14: =SUM(E12:E13) -> 0 | F14: =SUM(F12:F13) -> 0 | G14: =SUM(G12:G13) -> 0 | H14: =SUM(H12:H13) -> 0 | I14: =SUM(I12:I13) -> 0 | J14: =SUM(J12:J13) -> 0 | ... L14: =SUM(L12:L13) -> 0 | M14: =SUM(C14:L14) -> 0
A15: 12 | B15: Shortening- 15 kg | M15: =SUM(C15:L15) -> 0
A16: 13 | B16: Total Yest | C16: =C11+C14 -> 0 | D16: =D11+D14 -> 0 | E16: =E11+E14 -> 0 | F16: =F11+F14 -> 0 | G16: =G11+G14 -> 0 | H16: =H11+H14 -> 0 | I16: =I11+I14 -> 0 | J16: =J11+J14 -> 0 | ... L16: =L11+L14 -> 0 | M16: =SUM(C16:L16) -> 0
A17: 14 | B17: Angle Dry Yeast 25g | M17: =SUM(C17:L17) -> 0
A18: 15 | B18: Angle Dry Yeast 50g | M18: =SUM(C18:L18) -> 0
A19: 16 | B19: Total Angle Dry Yeast | C19: =SUM(C17:C18) -> 0 | D19: =SUM(D17:D18) -> 0 | E19: =SUM(E17:E18) -> 0 | F19: =SUM(F17:F18) -> 0 | G19: =SUM(G17:G18) -> 0 | H19: =SUM(H17:H18) -> 0 | I19: =SUM(I17:I18) -> 0 | J19: =SUM(J17:J18) -> 0 | ... M19: =SUM(M17:M18) -> 0
A20: 17 | B20: Mitra Margerine (Bakers compound -15kg) | M20: =SUM(C20:L20) -> 0
A21: 18 | B21: Mitra Margerine (Blue Lable) - 15kg | M21: =SUM(C21:L21) -> 0
A22: 19 | B22: Mitra - (Bun Compound 15Kg) | M22: =SUM(C22:L22) -> 0
A23: 20 | B23: Bakers Star Multy Purpes 15kg | M23: =SUM(C23:L23) -> 0
A24: 21 | B24: Bakers Star Primum Cake 15kg | M24: =SUM(C24:L24) -> 0
A25: 22 | B25: Mitra 15Kg (Bread Compound 15Kg) | M25: =SUM(C25:L25) -> 0
A26: 23 | B26: Bakers Star Pastry Margareen 15kg | M26: =SUM(C26:L26) -> 0
A27: 24 | B27: Bakers Star Creming Fat Margareen 15kg | M27: =SUM(C27:L27) -> 0
A28: 25 | B28: Total Magrgering | C28: =SUM(C20:C27) -> 0 | D28: =SUM(D20:D27) -> 0 | E28: =SUM(E20:E27) -> 0 | F28: =SUM(F20:F27) -> 0 | G28: =SUM(G20:G27) -> 0 | H28: =SUM(H20:H27) -> 0 | I28: =SUM(I20:I27) -> 0 | J28: =SUM(J20:J27) -> 0 | ... L28: =SUM(L20:L27) -> 0 | M28: =SUM(C28:L28) -> 0
A29: 26 | B29: Som-Chai 25kg bag | M29: =SUM(C29:L29) -> 0
A30: 27 | B30: Som-Chai G1 25kg bag | M30: =SUM(C30:L30) -> 0
A31: 28 | B31: Bread Improver- 01kg(LD-500) | M31: =SUM(C31:L31) -> 0
A32: 29 | B32: Bread Improver- 01kg(A-800) | M32: =SUM(C32:L32) -> 0
A33: 30 | B33: Som-Chai G2 25kg bag | M33: =SUM(C33:L33) -> 0
A34: 31 | B34: Som-Chai G2 1kg Pkt | M34: =SUM(C34:L34) -> 0
A35: 32 | B35: Som-Chai G2 350g Pkt | M35: =SUM(C35:L35) -> 0
A36: 33 | B36: Pan Grease- 5L | M36: =SUM(C36:L36) -> 0
A37: 34 | B37: Pan Grease- 20L | M37: =SUM(C37:L37) -> 0
A38: 35 | B38: Hybrid Noodles (Red) | M38: =SUM(C38:L38) -> 0
A39: 36 | B39: Isi PVD 400g | M39: =SUM(C39:L39) -> 0
A40: 37 | B40: Isi 1kg | M40: =SUM(C40:L40) -> 0
...

Sheet 12
A1: Daily achievement sheet (Van/Cluster/Singel /Welimada/DLS Oparations)
A2: Sr | B2: Item Description | M2: ASE
B3: RMS Items | C3: Avissawella | D3: Rathnapura | E3: Hanwella | F3: Horana | G3: Balangoda | H3: Piliyandala | M3: Tatal (B)
A4: 1 | B4: High Sugar- 500gr (Angel) | M4: =SUM(C4:L4) -> 0
A5: 2 | B5: Low Sugar -450gr (Angle) | M5: =SUM(C5:L5) -> 0
A6: 3 | B6: Low Sugar -500gr (Angle) | M6: =SUM(C6:L6) -> 0
A7: 4 | B7: Gloripan Instant Dry Yeast (High Sugar) 500g | M7: =SUM(C7:L7) -> 0
A8: 5 | B8: Gloripan Instant Dry Yeast (Low Sugar) 500g | M8: =SUM(C8:L8) -> 0
A9: 6 | B9: 2 In 1 Yeast 500gr (Low Suger) | M9: =SUM(C9:L9) -> 0
A10: 7 | B10: 2 In 1 Yeast 500gr (High Suger) | M10: =SUM(C10:L10) -> 0
A11: 8 | B11: Bakery Yest total | C11: =SUM(C4:C10) -> 0 | D11: =SUM(D4:D10) -> 0 | E11: =SUM(E4:E10) -> 0 | F11: =SUM(F4:F10) -> 0 | G11: =SUM(G4:G10) -> 0 | H11: =SUM(H4:H10) -> 0 | I11: =SUM(I4:I10) -> 0 | J11: =SUM(J4:J10) -> 0 | ... L11: =SUM(L4:L10) -> 0 | M11: =SUM(C11:L11) -> 0
A12: 9 | B12: Instant Leaven -450gr | M12: =SUM(C12:L12) -> 0
A13: 10 | B13: Instant Leaven -500gr | M13: =SUM(C13:L13) -> 0
A14: 11 | B14: Leaven Total | C14: =SUM(C12:C13) -> 0 | D14: =SUM(D12:D13) -> 0 | E14: =SUM(E12:E13) -> 0 | F14: =SUM(F12:F13) -> 0 | G14: =SUM(G12:G13) -> 0 | H14: =SUM(H12:H13) -> 0 | I14: =SUM(I12:I13) -> 0 | J14: =SUM(J12:J13) -> 0 | ... L14: =SUM(L12:L13) -> 0 | M14: =SUM(C14:L14) -> 0
A15: 12 | B15: Shortening- 15 kg | M15: =SUM(C15:L15) -> 0
A16: 13 | B16: Total Yest | C16: =C11+C14 -> 0 | D16: =D11+D14 -> 0 | E16: =E11+E14 -> 0 | F16: =F11+F14 -> 0 | G16: =G11+G14 -> 0 | H16: =H11+H14 -> 0 | I16: =I11+I14 -> 0 | J16: =J11+J14 -> 0 | ... L16: =L11+L14 -> 0 | M16: =SUM(C16:L16) -> 0
A17: 14 | B17: Angle Dry Yeast 25g | M17: =SUM(C17:L17) -> 0
A18: 15 | B18: Angle Dry Yeast 50g | M18: =SUM(C18:L18) -> 0
A19: 16 | B19: Total Angle Dry Yeast | C19: =SUM(C17:C18) -> 0 | D19: =SUM(D17:D18) -> 0 | E19: =SUM(E17:E18) -> 0 | F19: =SUM(F17:F18) -> 0 | G19: =SUM(G17:G18) -> 0 | H19: =SUM(H17:H18) -> 0 | I19: =SUM(I17:I18) -> 0 | J19: =SUM(J17:J18) -> 0 | ... M19: =SUM(M17:M18) -> 0
A20: 17 | B20: Mitra Margerine (Bakers compound -15kg) | M20: =SUM(C20:L20) -> 0
A21: 18 | B21: Mitra Margerine (Blue Lable) - 15kg | M21: =SUM(C21:L21) -> 0
A22: 19 | B22: Mitra - (Bun Compound 15Kg) | M22: =SUM(C22:L22) -> 0
A23: 20 | B23: Bakers Star Multy Purpes 15kg | M23: =SUM(C23:L23) -> 0
A24: 21 | B24: Bakers Star Primum Cake 15kg | M24: =SUM(C24:L24) -> 0
A25: 22 | B25: Mitra 15Kg (Bread Compound 15Kg) | M25: =SUM(C25:L25) -> 0
A26: 23 | B26: Bakers Star Pastry Margareen 15kg | M26: =SUM(C26:L26) -> 0
A27: 24 | B27: Bakers Star Creming Fat Margareen 15kg | M27: =SUM(C27:L27) -> 0
A28: 25 | B28: Total Magrgering | C28: =SUM(C20:C27) -> 0 | D28: =SUM(D20:D27) -> 0 | E28: =SUM(E20:E27) -> 0 | F28: =SUM(F20:F27) -> 0 | G28: =SUM(G20:G27) -> 0 | H28: =SUM(H20:H27) -> 0 | I28: =SUM(I20:I27) -> 0 | J28: =SUM(J20:J27) -> 0 | ... L28: =SUM(L20:L27) -> 0 | M28: =SUM(C28:L28) -> 0
A29: 26 | B29: Som-Chai 25kg bag | M29: =SUM(C29:L29) -> 0
A30: 27 | B30: Som-Chai G1 25kg bag | M30: =SUM(C30:L30) -> 0
A31: 28 | B31: Bread Improver- 01kg(LD-500) | M31: =SUM(C31:L31) -> 0
A32: 29 | B32: Bread Improver- 01kg(A-800) | M32: =SUM(C32:L32) -> 0
A33: 30 | B33: Som-Chai G2 25kg bag | M33: =SUM(C33:L33) -> 0
A34: 31 | B34: Som-Chai G2 1kg Pkt | M34: =SUM(C34:L34) -> 0
A35: 32 | B35: Som-Chai G2 350g Pkt | M35: =SUM(C35:L35) -> 0
A36: 33 | B36: Pan Grease- 5L | M36: =SUM(C36:L36) -> 0
A37: 34 | B37: Pan Grease- 20L | M37: =SUM(C37:L37) -> 0
A38: 35 | B38: Hybrid Noodles (Red) | M38: =SUM(C38:L38) -> 0
A39: 36 | B39: Isi PVD 400g | M39: =SUM(C39:L39) -> 0
A40: 37 | B40: Isi 1kg | M40: =SUM(C40:L40) -> 0
...

Sheet 13
A1: Daily achievement sheet (Van/Cluster/Singel /Welimada/DLS Oparations)
A2: Sr | B2: Item Description | M2: ASE
B3: RMS Items | C3: Avissawella | D3: Rathnapura | E3: Hanwella | F3: Horana | G3: Balangoda | H3: Piliyandala | M3: Tatal (B)
A4: 1 | B4: High Sugar- 500gr (Angel) | M4: =SUM(C4:L4) -> 0
A5: 2 | B5: Low Sugar -450gr (Angle) | M5: =SUM(C5:L5) -> 0
A6: 3 | B6: Low Sugar -500gr (Angle) | M6: =SUM(C6:L6) -> 0
A7: 4 | B7: Gloripan Instant Dry Yeast (High Sugar) 500g | M7: =SUM(C7:L7) -> 0
A8: 5 | B8: Gloripan Instant Dry Yeast (Low Sugar) 500g | M8: =SUM(C8:L8) -> 0
A9: 6 | B9: 2 In 1 Yeast 500gr (Low Suger) | M9: =SUM(C9:L9) -> 0
A10: 7 | B10: 2 In 1 Yeast 500gr (High Suger) | M10: =SUM(C10:L10) -> 0
A11: 8 | B11: Bakery Yest total | C11: =SUM(C4:C10) -> 0 | D11: =SUM(D4:D10) -> 0 | E11: =SUM(E4:E10) -> 0 | F11: =SUM(F4:F10) -> 0 | G11: =SUM(G4:G10) -> 0 | H11: =SUM(H4:H10) -> 0 | I11: =SUM(I4:I10) -> 0 | J11: =SUM(J4:J10) -> 0 | ... L11: =SUM(L4:L10) -> 0 | M11: =SUM(C11:L11) -> 0
A12: 9 | B12: Instant Leaven -450gr | M12: =SUM(C12:L12) -> 0
A13: 10 | B13: Instant Leaven -500gr | M13: =SUM(C13:L13) -> 0
A14: 11 | B14: Leaven Total | C14: =SUM(C12:C13) -> 0 | D14: =SUM(D12:D13) -> 0 | E14: =SUM(E12:E13) -> 0 | F14: =SUM(F12:F13) -> 0 | G14: =SUM(G12:G13) -> 0 | H14: =SUM(H12:H13) -> 0 | I14: =SUM(I12:I13) -> 0 | J14: =SUM(J12:J13) -> 0 | ... L14: =SUM(L12:L13) -> 0 | M14: =SUM(C14:L14) -> 0
A15: 12 | B15: Shortening- 15 kg | M15: =SUM(C15:L15) -> 0
A16: 13 | B16: Total Yest | C16: =C11+C14 -> 0 | D16: =D11+D14 -> 0 | E16: =E11+E14 -> 0 | F16: =F11+F14 -> 0 | G16: =G11+G14 -> 0 | H16: =H11+H14 -> 0 | I16: =I11+I14 -> 0 | J16: =J11+J14 -> 0 | ... L16: =L11+L14 -> 0 | M16: =SUM(C16:L16) -> 0
A17: 14 | B17: Angle Dry Yeast 25g | M17: =SUM(C17:L17) -> 0
A18: 15 | B18: Angle Dry Yeast 50g | M18: =SUM(C18:L18) -> 0
A19: 16 | B19: Total Angle Dry Yeast | C19: =SUM(C17:C18) -> 0 | D19: =SUM(D17:D18) -> 0 | E19: =SUM(E17:E18) -> 0 | F19: =SUM(F17:F18) -> 0 | G19: =SUM(G17:G18) -> 0 | H19: =SUM(H17:H18) -> 0 | I19: =SUM(I17:I18) -> 0 | J19: =SUM(J17:J18) -> 0 | ... M19: =SUM(M17:M18) -> 0
A20: 17 | B20: Mitra Margerine (Bakers compound -15kg) | M20: =SUM(C20:L20) -> 0
A21: 18 | B21: Mitra Margerine (Blue Lable) - 15kg | M21: =SUM(C21:L21) -> 0
A22: 19 | B22: Mitra - (Bun Compound 15Kg) | M22: =SUM(C22:L22) -> 0
A23: 20 | B23: Bakers Star Multy Purpes 15kg | M23: =SUM(C23:L23) -> 0
A24: 21 | B24: Bakers Star Primum Cake 15kg | M24: =SUM(C24:L24) -> 0
A25: 22 | B25: Mitra 15Kg (Bread Compound 15Kg) | M25: =SUM(C25:L25) -> 0
A26: 23 | B26: Bakers Star Pastry Margareen 15kg | M26: =SUM(C26:L26) -> 0
A27: 24 | B27: Bakers Star Creming Fat Margareen 15kg | M27: =SUM(C27:L27) -> 0
A28: 25 | B28: Total Magrgering | C28: =SUM(C20:C27) -> 0 | D28: =SUM(D20:D27) -> 0 | E28: =SUM(E20:E27) -> 0 | F28: =SUM(F20:F27) -> 0 | G28: =SUM(G20:G27) -> 0 | H28: =SUM(H20:H27) -> 0 | I28: =SUM(I20:I27) -> 0 | J28: =SUM(J20:J27) -> 0 | ... L28: =SUM(L20:L27) -> 0 | M28: =SUM(C28:L28) -> 0
A29: 26 | B29: Som-Chai 25kg bag | M29: =SUM(C29:L29) -> 0
A30: 27 | B30: Som-Chai G1 25kg bag | M30: =SUM(C30:L30) -> 0
A31: 28 | B31: Bread Improver- 01kg(LD-500) | M31: =SUM(C31:L31) -> 0
A32: 29 | B32: Bread Improver- 01kg(A-800) | M32: =SUM(C32:L32) -> 0
A33: 30 | B33: Som-Chai G2 25kg bag | M33: =SUM(C33:L33) -> 0
A34: 31 | B34: Som-Chai G2 1kg Pkt | M34: =SUM(C34:L34) -> 0
A35: 32 | B35: Som-Chai G2 350g Pkt | M35: =SUM(C35:L35) -> 0
A36: 33 | B36: Pan Grease- 5L | M36: =SUM(C36:L36) -> 0
A37: 34 | B37: Pan Grease- 20L | M37: =SUM(C37:L37) -> 0
A38: 35 | B38: Hybrid Noodles (Red) | M38: =SUM(C38:L38) -> 0
A39: 36 | B39: Isi PVD 400g | M39: =SUM(C39:L39) -> 0
A40: 37 | B40: Isi 1kg | M40: =SUM(C40:L40) -> 0
...

Sheet 14
A1: Daily achievement sheet (Van/Cluster/Singel /Welimada/DLS Oparations)
A2: Sr | B2: Item Description | M2: ASE
B3: RMS Items | C3: Avissawella | D3: Rathnapura | E3: Hanwella | F3: Horana | G3: Balangoda | H3: Piliyandala | M3: Tatal (B)
A4: 1 | B4: High Sugar- 500gr (Angel) | M4: =SUM(C4:L4) -> 0
A5: 2 | B5: Low Sugar -450gr (Angle) | M5: =SUM(C5:L5) -> 0
A6: 3 | B6: Low Sugar -500gr (Angle) | M6: =SUM(C6:L6) -> 0
A7: 4 | B7: Gloripan Instant Dry Yeast (High Sugar) 500g | M7: =SUM(C7:L7) -> 0
A8: 5 | B8: Gloripan Instant Dry Yeast (Low Sugar) 500g | M8: =SUM(C8:L8) -> 0
A9: 6 | B9: 2 In 1 Yeast 500gr (Low Suger) | M9: =SUM(C9:L9) -> 0
A10: 7 | B10: 2 In 1 Yeast 500gr (High Suger) | M10: =SUM(C10:L10) -> 0
A11: 8 | B11: Bakery Yest total | C11: =SUM(C4:C10) -> 0 | D11: 1 | E11: =SUM(E4:E10) -> 0 | F11: =SUM(F4:F10) -> 0 | G11: =SUM(G4:G10) -> 0 | H11: =SUM(H4:H10) -> 0 | I11: =SUM(I4:I10) -> 0 | J11: =SUM(J4:J10) -> 0 | K11: =SUM(K4:K10) -> 0 | L11: =SUM(L4:L10) -> 0 | M11: =SUM(C11:L11) -> 1
A12: 9 | B12: Instant Leaven -450gr | M12: =SUM(C12:L12) -> 0
A13: 10 | B13: Instant Leaven -500gr | M13: =SUM(C13:L13) -> 0
A14: 11 | B14: Leaven Total | C14: =SUM(C12:C13) -> 0 | D14: =SUM(D12:D13) -> 0 | E14: =SUM(E12:E13) -> 0 | F14: =SUM(F12:F13) -> 0 | G14: =SUM(G12:G13) -> 0 | H14: =SUM(H12:H13) -> 0 | I14: =SUM(I12:I13) -> 0 | J14: =SUM(J12:J13) -> 0 | ... L14: =SUM(L12:L13) -> 0 | M14: =SUM(C14:L14) -> 0
A15: 12 | B15: Shortening- 15 kg | M15: =SUM(C15:L15) -> 0
A16: 13 | B16: Total Yest | C16: =C11+C14 -> 0 | D16: =D11+D14 -> 1 | E16: =E11+E14 -> 0 | F16: =F11+F14 -> 0 | G16: =G11+G14 -> 0 | H16: =H11+H14 -> 0 | I16: =I11+I14 -> 0 | J16: =J11+J14 -> 0 | ... L16: =L11+L14 -> 0 | M16: =SUM(C16:L16) -> 1
A17: 14 | B17: Angle Dry Yeast 25g | M17: =SUM(C17:L17) -> 0
A18: 15 | B18: Angle Dry Yeast 50g | M18: =SUM(C18:L18) -> 0
A19: 16 | B19: Total Angle Dry Yeast | C19: =SUM(C17:C18) -> 0 | D19: =SUM(D17:D18) -> 0 | E19: =SUM(E17:E18) -> 0 | F19: =SUM(F17:F18) -> 0 | G19: =SUM(G17:G18) -> 0 | H19: =SUM(H17:H18) -> 0 | I19: =SUM(I17:I18) -> 0 | J19: =SUM(J17:J18) -> 0 | ... M19: =SUM(M17:M18) -> 0
A20: 17 | B20: Mitra Margerine (Bakers compound -15kg) | M20: =SUM(C20:L20) -> 0
A21: 18 | B21: Mitra Margerine (Blue Lable) - 15kg | M21: =SUM(C21:L21) -> 0
A22: 19 | B22: Mitra - (Bun Compound 15Kg) | M22: =SUM(C22:L22) -> 0
A23: 20 | B23: Bakers Star Multy Purpes 15kg | M23: =SUM(C23:L23) -> 0
A24: 21 | B24: Bakers Star Primum Cake 15kg | M24: =SUM(C24:L24) -> 0
A25: 22 | B25: Mitra 15Kg (Bread Compound 15Kg) | M25: =SUM(C25:L25) -> 0
A26: 23 | B26: Bakers Star Pastry Margareen 15kg | M26: =SUM(C26:L26) -> 0
A27: 24 | B27: Bakers Star Creming Fat Margareen 15kg | M27: =SUM(C27:L27) -> 0
A28: 25 | B28: Total Magrgering | C28: =SUM(C20:C27) -> 0 | D28: =SUM(D20:D27) -> 0 | E28: =SUM(E20:E27) -> 0 | F28: =SUM(F20:F27) -> 0 | G28: =SUM(G20:G27) -> 0 | H28: =SUM(H20:H27) -> 0 | I28: =SUM(I20:I27) -> 0 | J28: =SUM(J20:J27) -> 0 | ... L28: =SUM(L20:L27) -> 0 | M28: =SUM(C28:L28) -> 0
A29: 26 | B29: Som-Chai 25kg bag | M29: =SUM(C29:L29) -> 0
A30: 27 | B30: Som-Chai G1 25kg bag | M30: =SUM(C30:L30) -> 0
A31: 28 | B31: Bread Improver- 01kg(LD-500) | M31: =SUM(C31:L31) -> 0
A32: 29 | B32: Bread Improver- 01kg(A-800) | M32: =SUM(C32:L32) -> 0
A33: 30 | B33: Som-Chai G2 25kg bag | M33: =SUM(C33:L33) -> 0
A34: 31 | B34: Som-Chai G2 1kg Pkt | M34: =SUM(C34:L34) -> 0
A35: 32 | B35: Som-Chai G2 350g Pkt | M35: =SUM(C35:L35) -> 0
A36: 33 | B36: Pan Grease- 5L | M36: =SUM(C36:L36) -> 0
A37: 34 | B37: Pan Grease- 20L | M37: =SUM(C37:L37) -> 0
A38: 35 | B38: Hybrid Noodles (Red) | M38: =SUM(C38:L38) -> 0
A39: 36 | B39: Isi PVD 400g | M39: =SUM(C39:L39) -> 0
A40: 37 | B40: Isi 1kg | M40: =SUM(C40:L40) -> 0
...

Sheet 15
A1: Daily achievement sheet (Van/Cluster/Singel /Welimada/DLS Oparations)
A2: Sr | B2: Item Description | M2: ASE
B3: RMS Items | C3: Avissawella | D3: Rathnapura | E3: Hanwella | F3: Horana | G3: Balangoda | H3: Piliyandala | M3: Tatal (B)
A4: 1 | B4: High Sugar- 500gr (Angel) | M4: =SUM(C4:L4) -> 0
A5: 2 | B5: Low Sugar -450gr (Angle) | M5: =SUM(C5:L5) -> 0
A6: 3 | B6: Low Sugar -500gr (Angle) | M6: =SUM(C6:L6) -> 0
A7: 4 | B7: Gloripan Instant Dry Yeast (High Sugar) 500g | M7: =SUM(C7:L7) -> 0
A8: 5 | B8: Gloripan Instant Dry Yeast (Low Sugar) 500g | M8: =SUM(C8:L8) -> 0
A9: 6 | B9: 2 In 1 Yeast 500gr (Low Suger) | M9: =SUM(C9:L9) -> 0
A10: 7 | B10: 2 In 1 Yeast 500gr (High Suger) | M10: =SUM(C10:L10) -> 0
A11: 8 | B11: Bakery Yest total | C11: =SUM(C4:C10) -> 0 | D11: =SUM(D4:D10) -> 0 | E11: =SUM(E4:E10) -> 0 | F11: =SUM(F4:F10) -> 0 | G11: =SUM(G4:G10) -> 0 | H11: =SUM(H4:H10) -> 0 | I11: =SUM(I4:I10) -> 0 | J11: =SUM(J4:J10) -> 0 | ... L11: =SUM(L4:L10) -> 0 | M11: =SUM(C11:L11) -> 0
A12: 9 | B12: Instant Leaven -450gr | M12: =SUM(C12:L12) -> 0
A13: 10 | B13: Instant Leaven -500gr | M13: =SUM(C13:L13) -> 0
A14: 11 | B14: Leaven Total | C14: =SUM(C12:C13) -> 0 | D14: =SUM(D12:D13) -> 0 | E14: =SUM(E12:E13) -> 0 | F14: =SUM(F12:F13) -> 0 | G14: =SUM(G12:G13) -> 0 | H14: =SUM(H12:H13) -> 0 | I14: =SUM(I12:I13) -> 0 | J14: =SUM(J12:J13) -> 0 | ... L14: =SUM(L12:L13) -> 0 | M14: =SUM(C14:L14) -> 0
A15: 12 | B15: Shortening- 15 kg | M15: =SUM(C15:L15) -> 0
A16: 13 | B16: Total Yest | C16: =C11+C14 -> 0 | D16: =D11+D14 -> 0 | E16: =E11+E14 -> 0 | F16: =F11+F14 -> 0 | G16: =G11+G14 -> 0 | H16: =H11+H14 -> 0 | I16: =I11+I14 -> 0 | J16: =J11+J14 -> 0 | ... L16: =L11+L14 -> 0 | M16: =SUM(C16:L16) -> 0
A17: 14 | B17: Angle Dry Yeast 25g | M17: =SUM(C17:L17) -> 0
A18: 15 | B18: Angle Dry Yeast 50g | M18: =SUM(C18:L18) -> 0
A19: 16 | B19: Total Angle Dry Yeast | C19: =SUM(C17:C18) -> 0 | D19: =SUM(D17:D18) -> 0 | E19: =SUM(E17:E18) -> 0 | F19: =SUM(F17:F18) -> 0 | G19: =SUM(G17:G18) -> 0 | H19: =SUM(H17:H18) -> 0 | I19: =SUM(I17:I18) -> 0 | J19: =SUM(J17:J18) -> 0 | ... M19: =SUM(M17:M18) -> 0
A20: 17 | B20: Mitra Margerine (Bakers compound -15kg) | M20: =SUM(C20:L20) -> 0
A21: 18 | B21: Mitra Margerine (Blue Lable) - 15kg | M21: =SUM(C21:L21) -> 0
A22: 19 | B22: Mitra - (Bun Compound 15Kg) | M22: =SUM(C22:L22) -> 0
A23: 20 | B23: Bakers Star Multy Purpes 15kg | M23: =SUM(C23:L23) -> 0
A24: 21 | B24: Bakers Star Primum Cake 15kg | M24: =SUM(C24:L24) -> 0
A25: 22 | B25: Mitra 15Kg (Bread Compound 15Kg) | M25: =SUM(C25:L25) -> 0
A26: 23 | B26: Bakers Star Pastry Margareen 15kg | M26: =SUM(C26:L26) -> 0
A27: 24 | B27: Bakers Star Creming Fat Margareen 15kg | M27: =SUM(C27:L27) -> 0
A28: 25 | B28: Total Magrgering | C28: =SUM(C20:C27) -> 0 | D28: =SUM(D20:D27) -> 0 | E28: =SUM(E20:E27) -> 0 | F28: =SUM(F20:F27) -> 0 | G28: =SUM(G20:G27) -> 0 | H28: =SUM(H20:H27) -> 0 | I28: =SUM(I20:I27) -> 0 | J28: =SUM(J20:J27) -> 0 | ... L28: =SUM(L20:L27) -> 0 | M28: =SUM(C28:L28) -> 0
A29: 26 | B29: Som-Chai 25kg bag | M29: =SUM(C29:L29) -> 0
A30: 27 | B30: Som-Chai G1 25kg bag | M30: =SUM(C30:L30) -> 0
A31: 28 | B31: Bread Improver- 01kg(LD-500) | M31: =SUM(C31:L31) -> 0
A32: 29 | B32: Bread Improver- 01kg(A-800) | M32: =SUM(C32:L32) -> 0
A33: 30 | B33: Som-Chai G2 25kg bag | M33: =SUM(C33:L33) -> 0
A34: 31 | B34: Som-Chai G2 1kg Pkt | M34: =SUM(C34:L34) -> 0
A35: 32 | B35: Som-Chai G2 350g Pkt | M35: =SUM(C35:L35) -> 0
A36: 33 | B36: Pan Grease- 5L | M36: =SUM(C36:L36) -> 0
A37: 34 | B37: Pan Grease- 20L | M37: =SUM(C37:L37) -> 0
A38: 35 | B38: Hybrid Noodles (Red) | M38: =SUM(C38:L38) -> 0
A39: 36 | B39: Isi PVD 400g | M39: =SUM(C39:L39) -> 0
A40: 37 | B40: Isi 1kg | M40: =SUM(C40:L40) -> 0
...

Sheet 16
A1: Daily achievement sheet (Van/Cluster/Singel /Welimada/DLS Oparations)
A2: Sr | B2: Item Description | M2: ASE
B3: RMS Items | C3: Avissawella | D3: Rathnapura | E3: Hanwella | F3: Horana | G3: Balangoda | H3: Piliyandala | M3: Tatal (B)
A4: 1 | B4: High Sugar- 500gr (Angel) | M4: =SUM(C4:L4) -> 0
A5: 2 | B5: Low Sugar -450gr (Angle) | M5: =SUM(C5:L5) -> 0
A6: 3 | B6: Low Sugar -500gr (Angle) | M6: =SUM(C6:L6) -> 0
A7: 4 | B7: Gloripan Instant Dry Yeast (High Sugar) 500g | M7: =SUM(C7:L7) -> 0
A8: 5 | B8: Gloripan Instant Dry Yeast (Low Sugar) 500g | M8: =SUM(C8:L8) -> 0
A9: 6 | B9: 2 In 1 Yeast 500gr (Low Suger) | M9: =SUM(C9:L9) -> 0
A10: 7 | B10: 2 In 1 Yeast 500gr (High Suger) | M10: =SUM(C10:L10) -> 0
A11: 8 | B11: Bakery Yest total | C11: =SUM(C4:C10) -> 0 | D11: =SUM(D4:D10) -> 0 | E11: =SUM(E4:E10) -> 0 | F11: =SUM(F4:F10) -> 0 | G11: =SUM(G4:G10) -> 0 | H11: =SUM(H4:H10) -> 0 | I11: =SUM(I4:I10) -> 0 | J11: =SUM(J4:J10) -> 0 | ... L11: =SUM(L4:L10) -> 0 | M11: =SUM(C11:L11) -> 0
A12: 9 | B12: Instant Leaven -450gr | M12: =SUM(C12:L12) -> 0
A13: 10 | B13: Instant Leaven -500gr | M13: =SUM(C13:L13) -> 0
A14: 11 | B14: Leaven Total | C14: =SUM(C12:C13) -> 0 | D14: =SUM(D12:D13) -> 0 | E14: =SUM(E12:E13) -> 0 | F14: =SUM(F12:F13) -> 0 | G14: =SUM(G12:G13) -> 0 | H14: =SUM(H12:H13) -> 0 | I14: =SUM(I12:I13) -> 0 | J14: =SUM(J12:J13) -> 0 | ... L14: =SUM(L12:L13) -> 0 | M14: =SUM(C14:L14) -> 0
A15: 12 | B15: Shortening- 15 kg | M15: =SUM(C15:L15) -> 0
A16: 13 | B16: Total Yest | C16: =C11+C14 -> 0 | D16: =D11+D14 -> 0 | E16: =E11+E14 -> 0 | F16: =F11+F14 -> 0 | G16: =G11+G14 -> 0 | H16: =H11+H14 -> 0 | I16: =I11+I14 -> 0 | J16: =J11+J14 -> 0 | ... L16: =L11+L14 -> 0 | M16: =SUM(C16:L16) -> 0
A17: 14 | B17: Angle Dry Yeast 25g | M17: =SUM(C17:L17) -> 0
A18: 15 | B18: Angle Dry Yeast 50g | M18: =SUM(C18:L18) -> 0
A19: 16 | B19: Total Angle Dry Yeast | C19: =SUM(C17:C18) -> 0 | D19: =SUM(D17:D18) -> 0 | E19: =SUM(E17:E18) -> 0 | F19: =SUM(F17:F18) -> 0 | G19: =SUM(G17:G18) -> 0 | H19: =SUM(H17:H18) -> 0 | I19: =SUM(I17:I18) -> 0 | J19: =SUM(J17:J18) -> 0 | ... M19: =SUM(M17:M18) -> 0
A20: 17 | B20: Mitra Margerine (Bakers compound -15kg) | M20: =SUM(C20:L20) -> 0
A21: 18 | B21: Mitra Margerine (Blue Lable) - 15kg | M21: =SUM(C21:L21) -> 0
A22: 19 | B22: Mitra - (Bun Compound 15Kg) | M22: =SUM(C22:L22) -> 0
A23: 20 | B23: Bakers Star Multy Purpes 15kg | M23: =SUM(C23:L23) -> 0
A24: 21 | B24: Bakers Star Primum Cake 15kg | M24: =SUM(C24:L24) -> 0
A25: 22 | B25: Mitra 15Kg (Bread Compound 15Kg) | M25: =SUM(C25:L25) -> 0
A26: 23 | B26: Bakers Star Pastry Margareen 15kg | M26: =SUM(C26:L26) -> 0
A27: 24 | B27: Bakers Star Creming Fat Margareen 15kg | M27: =SUM(C27:L27) -> 0
A28: 25 | B28: Total Magrgering | C28: =SUM(C20:C27) -> 0 | D28: =SUM(D20:D27) -> 0 | E28: =SUM(E20:E27) -> 0 | F28: =SUM(F20:F27) -> 0 | G28: =SUM(G20:G27) -> 0 | H28: =SUM(H20:H27) -> 0 | I28: =SUM(I20:I27) -> 0 | J28: =SUM(J20:J27) -> 0 | ... L28: =SUM(L20:L27) -> 0 | M28: =SUM(C28:L28) -> 0
A29: 26 | B29: Som-Chai 25kg bag | M29: =SUM(C29:L29) -> 0
A30: 27 | B30: Som-Chai G1 25kg bag | M30: =SUM(C30:L30) -> 0
A31: 28 | B31: Bread Improver- 01kg(LD-500) | M31: =SUM(C31:L31) -> 0
A32: 29 | B32: Bread Improver- 01kg(A-800) | M32: =SUM(C32:L32) -> 0
A33: 30 | B33: Som-Chai G2 25kg bag | M33: =SUM(C33:L33) -> 0
A34: 31 | B34: Som-Chai G2 1kg Pkt | M34: =SUM(C34:L34) -> 0
A35: 32 | B35: Som-Chai G2 350g Pkt | M35: =SUM(C35:L35) -> 0
A36: 33 | B36: Pan Grease- 5L | M36: =SUM(C36:L36) -> 0
A37: 34 | B37: Pan Grease- 20L | M37: =SUM(C37:L37) -> 0
A38: 35 | B38: Hybrid Noodles (Red) | M38: =SUM(C38:L38) -> 0
